Workbook
Name Slicer_Region1: #N/A

Sheet Detail1
A1: Details for Margin % - Product_Name: Tanishq Maxi Dress Wine
A3: Invoice No | B3: Invoice Date | C3: Year | D3: Month | E3: Target Key | F3: Customer_ID | G3: Customer Name | H3: Gender | I3: City | J3: State | K3: Membership | L3: Product_ID | M3: Product_Name | N3: Category | O3: Sub Category | P3: Brand | Q3: Store_ID | R3: Store Name | S3: Monthly Target | T3: Region | U3: Employee_ID | V3: Employee Name | W3: Quantity | X3: Unit Price | Y3: Discount % | Z3: Discount Amount | AA3: GST % | AB3: GST Amount | AC3: Sales Amount | AD3: Cost Amount | AE3: Profit | AF3: Payment Modee | AG3: Profit Margin % | AH3: Payment Mode | AI3: Sales Channel | AJ3: Return Status | AK3: Order Time | AL3: Order Period | AM3: Day Type
A4: INV102874 | B4: 45567 | C4: 2024 | D4: Oct | E4: STR026-2024-Oct | F4: CUST0346 | G4: Malathi Achari | H4: Female | I4: Bengaluru | J4: Karnataka | K4: Regular | L4: PRD0169 | M4: Tanishq Maxi Dress Wine | N4: Women Dresses | O4: Maxi Dress | P4: Tanishq | Q4: STR026 | R4: TrendMart Guntur Standard | S4: 2500000 | T4: South Zone 3 | U4: EMP0073 | V4: Sathish Sundaram | W4: 2 | X4: 1768.99 | Y4: 20 | Z4: 707.6 | AA4: 12 | AB4: 339.65 | AC4: 3170.03 | AD4: 2814.66 | AE4: 15.72 | AF4: EMI | AG4: 0.0049589436 | AH4: EMI | AI4: Offline | AJ4: Not Returned | AK4: 13:16 | AL4: Afternoon | AM4: Weekday
A5: INV102745 | B5: 45602 | C5: 2024 | D5: Nov | E5: STR017-2024-Nov | F5: CUST0131 | G5: Jyothi Achari | H5: Female | I5: Tiruchirappalli | J5: Tamil Nadu | K5: Regular | L5: PRD0169 | M5: Tanishq Maxi Dress Wine | N5: Women Dresses | O5: Maxi Dress | P5: Tanishq | Q5: STR017 | R5: TrendMart Kurnool Standard | S5: 2500000 | T5: South Zone 3 | U5: EMP0100 | V5: Priya Balasubramaniam | W5: 1 | X5: 1733.53 | Y5: 20 | Z5: 346.71 | AA5: 12 | AB5: 166.42 | AC5: 1553.24 | AD5: 1407.33 | AE5: -20.51 | AF5: UPI | AG5: -0.013204656 | AH5: UPI | AI5: Online | AJ5: Not Returned | AK5: 15:39 | AL5: Afternoon | AM5: Weekday
A6: INV102659 | B6: 45399 | C6: 2024 | D6: Apr | E6: STR098-2024-Apr | F6: CUST0410 | G6: Vasanthi Bhat | H6: Female | I6: Kalaburagi | J6: Karnataka | K6: Regular | L6: PRD0169 | M6: Tanishq Maxi Dress Wine | N6: Women Dresses | O6: Maxi Dress | P6: Tanishq | Q6: STR098 | R6: TrendMart Guntur High Street | S6: 1200000 | T6: South Zone 3 | U6: EMP0170 | V6: Jyothi Prasad | W6: 4 | X6: 1690.9 | Y6: 0 | Z6: 0 | AA6: 12 | AB6: 811.63 | AC6: 7575.23 | AD6: 5629.32 | AE6: 1134.28 | AF6: UPI | AG6: 0.14973539 | AH6: UPI | AI6: Offline | AJ6: Not Returned | AK6: 11:16 | AL6: Morning | AM6: Weekday
A7: INV102537 | B7: 45622 | C7: 2024 | D7: Nov | E7: STR113-2024-Nov | F7: CUST0656 | G7: Chandrika Kamath | H7: Female | I7: Dindigul | J7: Tamil Nadu | K7: Platinum | L7: PRD0169 | M7: Tanishq Maxi Dress Wine | N7: Women Dresses | O7: Maxi Dress | P7: Tanishq | Q7: STR113 | R7: TrendMart Mangaluru High Street | S7: 2000000 | T7: South Zone 2 | U7: EMP0149 | V7: Vasanthi Kamath | W7: 1 | X7: 1742.37 | Y7: 20 | Z7: 348.47 | AA7: 12 | AB7: 167.27 | AC7: 1561.17 | AD7: 1407.33 | AE7: -13.43 | AF7: UPI | AG7: -0.0086025225 | AH7: UPI | AI7: Online | AJ7: Not Returned | AK7: 10:54 | AL7: Morning | AM7: Weekday
A8: INV102194 | B8: 45587 | C8: 2024 | D8: Oct | E8: STR037-2024-Oct | F8: CUST0687 | G8: Sanjay Gopalakrishnan | H8: Male | I8: Guntur | J8: Andhra Pradesh | K8: Regular | L8: PRD0169 | M8: Tanishq Maxi Dress Wine | N8: Women Dresses | O8: Maxi Dress | P8: Tanishq | Q8: STR037 | R8: TrendMart Vijayawada High Street | S8: 1000000 | T8: South Zone 3 | U8: EMP0073 | V8: Sathish Sundaram | W8: 1 | X8: 1829.49 | Y8: 30 | Z8: 548.85 | AA8: 12 | AB8: 153.68 | AC8: 1434.32 | AD8: 1407.33 | AE8: -126.69 | AF8: Cash | AG8: -0.08832757 | AH8: Cash | AI8: Offline | AJ8: Not Returned | AK8: 21:27 | AL8: Night | AM8: Weekday
A9: INV102170 | B9: 45710 | C9: 2025 | D9: Feb | E9: STR077-2025-Feb | F9: CUST0789 | G9: Rohit Gupta | H9: Male | I9: Kollam | J9: Kerala | K9: Gold | L9: PRD0169 | M9: Tanishq Maxi Dress Wine | N9: Women Dresses | O9: Maxi Dress | P9: Tanishq | Q9: STR077 | R9: TrendMart Hyderabad Mall Kiosk | S9: 2500000 | T9: South Zone 2 | U9: EMP0149 | V9: Vasanthi Kamath | W9: 2 | X9: 1860.09 | Y9: 15 | Z9: 558.03 | AA9: 12 | AB9: 379.46 | AC9: 3541.61 | AD9: 2814.66 | AE9: 347.49 | AF9: Net Banking | AG9: 0.098116393 | AH9: Net Banking | AI9: Offline | AJ9: Not Returned | AK9: 21:14 | AL9: Night | AM9: Weekend
A10: INV102111 | B10: 45628 | C10: 2024 | D10: Dec | E10: STR081-2024-Dec | F10: CUST0289 | G10: Balaji Kumar | H10: Male | I10: Warangal | J10: Telangana | K10: Silver | L10: PRD0169 | M10: Tanishq Maxi Dress Wine | N10: Women Dresses | O10: Maxi Dress | P10: Tanishq | Q10: STR081 | R10: TrendMart Alappuzha Outlet | S10: 2500000 | T10: South Zone 1 | U10: EMP0206 | V10: Arjun Krishnan | W10: 2 | X10: 1829 | Y10: 10 | Z10: 365.8 | AA10: 12 | AB10: 395.06 | AC10: 3687.26 | AD10: 2814.66 | AE10: 477.54 | AF10: Credit Card | AG10: 0.1295108 | AH10: Credit Card | AI10: Online | AJ10: Not Returned | AK10: 19:19 | AL10: Evening | AM10: Weekday
A11: INV102076 | B11: 45498 | C11: 2024 | D11: Jul | E11: STR040-2024-Jul | F11: CUST0226 | G11: Hariharan Kamath | H11: Male | I11: Vellore | J11: Tamil Nadu | K11: Regular | L11: PRD0169 | M11: Tanishq Maxi Dress Wine | N11: Women Dresses | O11: Maxi Dress | P11: Tanishq | Q11: STR040 | R11: TrendMart Nizamabad Mall Kiosk | S11: 1200000 | T11: South Zone 2 | U11: EMP0240 | V11: Gopal Prasad | W11: 1 | X11: 1835.19 | Y11: 0 | Z11: 0 | AA11: 12 | AB11: 220.22 | AC11: 2055.41 | AD11: 1407.33 | AE11: 427.86 | AF11: Credit Card | AG11: 0.20816285 | AH11: Credit Card | AI11: Offline | AJ11: Not Returned | AK11: 13:15 | AL11: Afternoon | AM11: Weekday
A12: INV101561 | B12: 45568 | C12: 2024 | D12: Oct | E12: STR033-2024-Oct | F12: CUST0239 | G12: Elango Reddy | H12: Male | I12: Visakhapatnam | J12: Andhra Pradesh | K12: Regular | L12: PRD0169 | M12: Tanishq Maxi Dress Wine | N12: Women Dresses | O12: Maxi Dress | P12: Tanishq | Q12: STR033 | R12: TrendMart Guntur Standard | S12: 2500000 | T12: South Zone 3 | U12: EMP0127 | V12: Chandra Reddy | W12: 1 | X12: 1719.04 | Y12: 25 | Z12: 429.76 | AA12: 12 | AB12: 154.71 | AC12: 1443.99 | AD12: 1407.33 | AE12: -118.05 | AF12: UPI | AG12: -0.081752644 | AH12: UPI | AI12: Offline | AJ12: Not Returned | AK12: 15:19 | AL12: Afternoon | AM12: Weekday
A13: INV101448 | B13: 45567 | C13: 2024 | D13: Oct | E13: STR063-2024-Oct | F13: CUST0471 | G13: Mahesh Menon | H13: Male | I13: Coimbatore | J13: Tamil Nadu | K13: Regular | L13: PRD0169 | M13: Tanishq Maxi Dress Wine | N13: Women Dresses | O13: Maxi Dress | P13: Tanishq | Q13: STR063 | R13: TrendMart Shivamogga Mall Kiosk | S13: 1200000 | T13: South Zone 2 | U13: EMP0225 | V13: Swathi Achari | W13: 1 | X13: 1797.13 | Y13: 25 | Z13: 449.28 | AA13: 12 | AB13: 161.74 | AC13: 1509.59 | AD13: 1407.33 | AE13: -59.48 | AF13: Credit Card | AG13: -0.039401427 | AH13: Credit Card | AI13: Offline | AJ13: Not Returned | AK13: 13:12 | AL13: Afternoon | AM13: Weekday
A14: INV101155 | B14: 45580 | C14: 2024 | D14: Oct | E14: STR048-2024-Oct | F14: CUST0051 | G14: Eswar Sharma | H14: Male | I14: Thiruvananthapuram | J14: Kerala | K14: Regular | L14: PRD0169 | M14: Tanishq Maxi Dress Wine | N14: Women Dresses | O14: Maxi Dress | P14: Tanishq | Q14: STR048 | R14: TrendMart Guntur High Street | S14: 1200000 | T14: South Zone 3 | U14: EMP0260 | V14: Malathi Varma | W14: 3 | X14: 1786.37 | Y14: 10 | Z14: 535.91 | AA14: 12 | AB14: 578.78 | AC14: 5401.98 | AD14: 4221.99 | AE14: 601.21 | AF14: Debit Card | AG14: 0.11129438 | AH14: Debit Card | AI14: Online | AJ14: Not Returned | AK14: 11:05 | AL14: Morning | AM14: Weekday
A15: INV101141 | B15: 45591 | C15: 2024 | D15: Oct | E15: STR012-2024-Oct | F15: CUST0256 | G15: Chandra Iyer | H15: Male | I15: Tirunelveli | J15: Tamil Nadu | K15: Silver | L15: PRD0169 | M15: Tanishq Maxi Dress Wine | N15: Women Dresses | O15: Maxi Dress | P15: Tanishq | Q15: STR012 | R15: TrendMart Vijayawada Mall Kiosk | S15: 2000000 | T15: South Zone 3 | U15: EMP0147 | V15: Yogesh Chettiar | W15: 1 | X15: 1850.69 | Y15: 5 | Z15: 92.53 | AA15: 12 | AB15: 210.98 | AC15: 1969.14 | AD15: 1407.33 | AE15: 350.83 | AF15: Cash | AG15: 0.17816407 | AH15: Cash | AI15: Offline | AJ15: Not Returned | AK15: 14:44 | AL15: Afternoon | AM15: Weekend
... A23: INV100166 | B23: 45658 | C23: 2025 | D23: Jan | E23: STR022-2025-Jan | F23: CUST0788 | G23: Eshwari Singh | H23: Female | I23: Kannur | J23: Kerala | K23: Regular | L23: PRD0169 | M23: Tanishq Maxi Dress Wine | N23: Women Dresses | O23: Maxi Dress | P23: Tanishq | Q23: STR022 | R23: TrendMart Shivamogga Outlet | S23: 800000 | T23: South Zone 2 | U23: EMP0100 | V23: Priya Balasubramaniam | W23: 3 | X23: 1783.67 | Y23: 20 | Z23: 1070.2 | AA23: 12 | AB23: 513.7 | AC23: 4794.51 | AD23: 4221.99 | AE23: 58.82 | AF23: UPI | AG23: 0.012268198 | AH23: UPI | AI23: Offline | AJ23: Not Returned | AK23: 10:25 | AL23: Morning | AM23: Weekday

Sheet Dashboard
A2: TrendMart
A3: Profitability Leakage Analysis
J29: High Sales- Low Profits Products | O29: Top 5 Brands By Profit | T29: KEY INSIGHTS & ACTIONS
J30: Row Labels | K30: Sales | L30: Profits | M30: Margin % | O30: Row Labels | P30: Sales | Q30: Profits | R30: Margin % | T30: 📈 Focus on High Sales – Low Margin Products
J31: Tanishq Maxi Dress Wine | K31: 63885.79 | L31: 4969.68 | M31: 0.063345287 | O31: GRT Jewellers | P31: 550505.3 | Q31: 128132.78 | R31: 0.21328364
J32: Woodland Sling Bag Peach | K32: 40839.31 | L32: 3490.37 | M32: 0.070909678 | O32: Max Fashion | P32: 452052.35 | Q32: 94595.74 | R32: 0.18738607 | T32: 🎯 Increase Online Sales Contribution
J33: Levi's Digital Watch Orange | K33: 37532.38 | L33: 2815.06 | M33: 0.0533215 | O33: Reebok | P33: 409555.3 | Q33: 93336.85 | R33: 0.22319684
J34: Reebok Leather Wallet Navy Blue | K34: 17896.42 | L34: 1299.91 | M34: 0.050616437 | O34: Global Desi | P34: 434134.43 | Q34: 86063.96 | R34: 0.2061576 | T34: 🔄 Reduce Return Rate
J35: Fabindia Slim Fit Peach | K35: 15645.48 | L35: -684.74 | M35: -0.057764362 | O35: Aurelia | P35: 477313.21 | Q35: 72324.22 | R35: 0.15839026

Sheet Calculations
A2: TOTAL SALES | C2: CURRENT MONTHLY AVG(SALES) | E2: CURRENT MONTHLY AVG(PROFIT) | G2: CURRENT MONTHLY AVG(AVG ORDER VAL)
A3: =SUM(Table2[Sales Amount]) -> 9227180 | C3: =AVERAGE(Sales_Transactions!AC7:AC2997) -> 3073.2408 | E3: =AVERAGE(Sales_Transactions!AE2870:AE2997) -> 558.1843 | G3: =SUM(Sales_Transactions!AC7:AC2997)/COUNTA(Sales_Transactions!AK7:AK2997) -> 3073.2408
A5: TOTAL PROFIT | C5: PREVIOUS MONTHLY AVG(SALES) | E5: PREVIOUS MONTHLY AVG(PROFIT) | G5: PREVIOUS MONTHLY AVG(AVG ORDER VAL)
A6: =SUM(Table2[Profit]) -> 1804518.5 | C6: =AVERAGE(Table2[Sales Amount]) -> 3075.7267 | E6: =AVERAGE(Table2[Profit]) -> 601.50618 | G6: =SUM(Table2[Sales Amount])/COUNTA(Table2[Order Time]) -> 3075.7267
A8: AVERAGE TRANSACTIONS | C8: SALES GROWTH | E8: PROFIT GROWTH | G8: AVG ORDER VALUE GROWTH
A9: =A3/A12 -> 3075.7267 | C9: =((C3-C6)/C6) -> -0.00080821147 | E9: =((E3-E6)/E6) -> -0.072022341 | G9: =((G3-G6)/G6) -> -0.00080821147
A11: TOTAL TRANSACTIONS | C11: =IF(Calculations!C9>=0,"▲ "&TEXT(Calculations!C9,"0.00%")&" vs Last Year","▼ "&TEXT(Calculations!C9,"0.00%")&" vs Last Year") -> ▼ -0.08% vs Last Year | E11: =IF(Calculations!E9>=0,"▲ "&TEXT(Calculations!E9,"0.00%")&" vs Last Year","▼ "&TEXT(Calculations!E9,"0.00%")&" vs Last Year") -> ▼ -7.20% vs Last Year | G11: =IF(Calculations!G9>=0,"▲ "&TEXT(Calculations!G9,"0.00%")&" vs Last Year","▼ "&TEXT(Calculations!G9,"0.00%")&" vs Last Year") -> ▼ -0.08% vs Last Year
A12: =COUNTA(Table2[Invoice No]) -> 3000
A14: PROFIT MARGIN | C14: TOTAL COST | E14: Sum of Sales Amount
A15: =E18/E15 -> 0.19556555 | C15: =SUM(Table2[Cost Amount]) -> 6596441.1 | E15: 9227180
A17: TOTAL QUANTITY | C17: Sum of Quantity | E17: Sum of Profit
A18: =SUM(Table2[Quantity]) -> 6118 | C18: 6118 | E18: 1804518.5
A20: TOTAL DISCOUNT | E20: Sum of Cost Amount
A21: =SUM(Table2[Discount Amount]) -> 1184202.8 | E21: 6596441.1
A23: AVERAGE DISCOUNT | E23: Count of Order Time
A24: =AVERAGE(Table2[Discount %])/100 -> 0.1257 | E24: 3000
A26: RETURN RATE
A27: =B32/B33 -> 0.049199085
A30: Row Labels | B30: Sum of Quantity
A31: Not Returned | B31: 5817
A32: Returned | B32: 301
A33: Grand Total | B33: 6118

Sheet Pivot_Table
A3: Row Labels | B3: Sum of Sales Amount | C3: Sum of Profit
A4: 2024 | B4: 7613439.2 | C4: 1489359.7
A5: Apr | B5: 683356.93 | C5: 132559.46
A6: May | B6: 715370.42 | C6: 143214.56
A7: Jun | B7: 706442.99 | C7: 126683.88
A8: Jul | B8: 575940.09 | C8: 110065.95
A9: Aug | B9: 624765.64 | C9: 122773.23
A10: Sep | B10: 842808.66 | C10: 177387.37
A11: Oct | B11: 1519147.1 | C11: 301165.34
A12: Nov | B12: 1054251.4 | C12: 194655.84
A13: Dec | B13: 891356.08 | C13: 180854.07
A14: 2025 | B14: 1613740.7 | C14: 315158.84
A15: Jan | B15: 305174.24 | C15: 54860.77
... A18: Grand Total | B18: 9227180 | C18: 1804518.5
A22: Row Labels | B22: Sum of Sales Amount | C22: Sum of Profit
A23: Women Sarees | B23: 1103017.8 | C23: 202347.57
A24: Handbags | B24: 994021.98 | C24: 213991.74
A25: Watches | B25: 937502.18 | C25: 181304.56
A26: Jewellery | B26: 850930.2 | C26: 150422.21
A27: Women Dresses | B27: 648333.43 | C27: 108303.11
A28: Footwear | B28: 521388.97 | C28: 89384.64
A29: Men Ethnic | B29: 508021.06 | C29: 96328.01
A30: Women Jeans | B30: 504452.21 | C30: 92155.45
A31: Women Kurtis | B31: 408431.14 | C31: 82676.47
A32: Winter Wear | B32: 390745.41 | C32: 82000.54
A33: Grand Total | B33: 6866844.4 | C33: 1298914.3
A49: Row Labels | B49: Sum of Sales Amount | C49: Sum of Cost Amount | D49: Sum of Profit | E49: Sum of Quantity
A50: Sling Bag | B50: 852042.14 | C50: 573553.51 | D50: 188653 | E50: 313
A51: Earrings | B51: 624597.34 | C51: 502154.51 | D51: 104250.66 | E51: 105
A52: Georgette Saree | B52: 470927.8 | C52: 334711 | D52: 85760.28 | E52: 154
A53: Digital Watch | B53: 369648.92 | C53: 268382.4 | D53: 61661.26 | E53: 93
A54: Shirt Dress | B54: 268165.83 | C54: 197365.25 | D54: 42068.57 | E54: 178
A55: Analog Watch | B55: 266092.36 | C55: 190371.93 | D55: 47210.54 | E55: 57
A56: Smart Watch | B56: 249297.22 | C56: 162993.29 | D56: 59593.51 | E56: 78
A57: Printed Saree | B57: 233659.75 | C57: 156760.65 | D57: 51864.11 | E57: 58
A58: Skinny Fit | B58: 223050.53 | C58: 158577.38 | D58: 43341.81 | E58: 185
A59: Slippers | B59: 210364.48 | C59: 144004.46 | D59: 43820.98 | E59: 88
A60: Cotton Saree | B60: 202834.9 | C60: 150333.72 | D60: 30768.88 | E60: 95
A61: Bootcut | B61: 197586.18 | C61: 139405.88 | D61: 37744.2 | E61: 148
... A125: Grand Total | B125: 9227180 | C125: 6596441.1 | D125: 1804518.5 | E125: 6118
...

Sheet Sales_Transactions
A1: Invoice No | B1: Invoice Date | C1: Year | D1: Month | E1: Target Key | F1: Customer_ID | G1: Customer Name | H1: Gender | I1: City | J1: State | K1: Membership | L1: Product_ID | M1: Product_Name | N1: Category | O1: Sub Category | P1: Brand | Q1: Store_ID | R1: Store Name | S1: Monthly Target | T1: Region | U1: Employee_ID | V1: Employee Name | W1: Quantity | X1: Unit Price | Y1: Discount % | Z1: Discount Amount | AA1: GST % | AB1: GST Amount | AC1: Sales Amount | AD1: Cost Amount | AE1: Profit | AF1: Payment Modee | AG1: Profit Margin % | AH1: Payment Mode | AI1: Sales Channel | AJ1: Return Status | AK1: Order Time | AL1: Order Period | AM1: Day Type
A2: INV100001 | B2: 45642 | C2: =YEAR(Table2[[#This Row],[Invoice Date]]) -> 2024 | D2: =TEXT(Table2[[#This Row],[Invoice Date]],"mmm") -> Dec | E2: =Table2[[#This Row],[Store_ID]]&"-"&Table2[[#This Row],[Year]]&"-"&Table2[[#This Row],[Month]] -> STR037-2024-Dec | F2: CUST0052 | G2: =_xlfn.XLOOKUP(Table2[[#This Row],[Customer_ID]],Table3[Customer_ID],Table3[Customer Name],"Not Found") -> Dhruv Achari | H2: =_xlfn.XLOOKUP(Table2[[#This Row],[Customer_ID]],Table3[Customer_ID],Table3[Gender],"Female") -> Male | I2: =_xlfn.XLOOKUP(Table2[[#This Row],[Customer_ID]],Table3[Customer_ID],Table3[City],"Missing Memebership") -> Kollam | J2: =_xlfn.XLOOKUP(Table2[[#This Row],[Customer_ID]],Table3[Customer_ID],Table3[State],"Karnataka") -> Kerala | K2: =_xlfn.XLOOKUP(Table2[[#This Row],[Customer_ID]],Table3[Customer_ID],Table3[Membership],"Regular") -> Regular | L2: PRD0200 | M2: =_xlfn.XLOOKUP(Table2[[#This Row],[Product_ID]],Table4[Product_ID],Table4[Product_Name],"Not Found") -> Pepe Jeans A-Line Kurti White | N2: =_xlfn.XLOOKUP(Table2[[#This Row],[Product_ID]],Table4[Product_ID],Table4[Category],"Not Found") -> Women Kurtis | O2: =_xlfn.XLOOKUP(Table2[[#This Row],[Product_ID]],Table4[Product_ID],Table4[Subcategory],"Not Found") -> A-Line Kurti | P2: =_xlfn.XLOOKUP(Table2[[#This Row],[Product_ID]],Table4[Product_ID],Table4[Brand],"Missing Brand") -> Pepe Jeans | Q2: STR037 | R2: =_xlfn.XLOOKUP(Table2[[#This Row],[Store_ID]],Table6[Store_ID],Table6[Store Name],"Not Found") -> TrendMart Vijayawada High Street | S2: =_xlfn.XLOOKUP(Table2[[#This Row],[Store_ID]],Table6[Store_ID],Table6[Monthly Target],"Missing Target") -> 1000000 | T2: =_xlfn.XLOOKUP(Table2[[#This Row],[Store_ID]],Table6[Store_ID],Table6[Region],"Not Found") -> South Zone 3 | U2: EMP0276 | V2: =_xlfn.XLOOKUP(Table2[[#This Row],[Employee_ID]],Table5[Employee_ID],Table5[Employee Name],"Not Found") -> Manoj Ramachandran | W2: 1 | X2: 749.84 | Y2: 10 | Z2: 74.98 | AA2: 5 | AB2: 33.74 | AC2: 708.6 | AD2: 496.67 | AE2: =(AC2-AD2-AB2) -> 178.19 | AF2: UPI | AG2: =IFERROR(Table2[[#This Row],[Profit]]/Table2[[#This Row],[Sales Amount]],0) -> 0.25146768 | AH2: =TRIM(Table2[[#This Row],[Payment Modee]]) -> UPI | AI2: Offline | AJ2: Not Returned | AK2: 18:16 | AL2: =IF(HOUR(Table2[[#This Row],[Order Time]])<12,"Morning",IF(HOUR(Table2[[#This Row],[Order Time]])<17,"Afternoon",IF(HOUR(Table2[[#This Row],[Order Time]])<21,"Evening","Night"))) -> Evening | AM2: Weekday
A3: INV100002 | B3: 45578 | C3: =YEAR(Table2[[#This Row],[Invoice Date]]) -> 2024 | D3: =TEXT(Table2[[#This Row],[Invoice Date]],"mmm") -> Oct | E3: =Table2[[#This Row],[Store_ID]]&"-"&Table2[[#This Row],[Year]]&"-"&Table2[[#This Row],[Month]] -> STR102-2024-Oct | F3: CUST0463 | G3: =_xlfn.XLOOKUP(Table2[[#This Row],[Customer_ID]],Table3[Customer_ID],Table3[Customer Name],"Not Found") -> Ashok Menon | H3: =_xlfn.XLOOKUP(Table2[[#This Row],[Customer_ID]],Table3[Customer_ID],Table3[Gender],"Female") -> Male | I3: =_xlfn.XLOOKUP(Table2[[#This Row],[Customer_ID]],Table3[Customer_ID],Table3[City],"Missing Memebership") -> Tumakuru | J3: =_xlfn.XLOOKUP(Table2[[#This Row],[Customer_ID]],Table3[Customer_ID],Table3[State],"Karnataka") -> Karnataka | K3: =_xlfn.XLOOKUP(Table2[[#This Row],[Customer_ID]],Table3[Customer_ID],Table3[Membership],"Regular") -> Regular | L3: PRD0245 | M3: =_xlfn.XLOOKUP(Table2[[#This Row],[Product_ID]],Table4[Product_ID],Table4[Product_Name],"Not Found") -> Reebok Round Neck Sky Blue | N3: =_xlfn.XLOOKUP(Table2[[#This Row],[Product_ID]],Table4[Product_ID],Table4[Category],"Not Found") -> Men T-Shirts | O3: =_xlfn.XLOOKUP(Table2[[#This Row],[Product_ID]],Table4[Product_ID],Table4[Subcategory],"Not Found") -> Round Neck | P3: =_xlfn.XLOOKUP(Table2[[#This Row],[Product_ID]],Table4[Product_ID],Table4[Brand],"Missing Brand") -> Reebok | Q3: STR102 | R3: =_xlfn.XLOOKUP(Table2[[#This Row],[Store_ID]],Table6[Store_ID],Table6[Store Name],"Not Found") -> TrendMart Tirunelveli High Street | S3: =_xlfn.XLOOKUP(Table2[[#This Row],[Store_ID]],Table6[Store_ID],Table6[Monthly Target],"Missing Target") -> 1000000 | T3: =_xlfn.XLOOKUP(Table2[[#This Row],[Store_ID]],Table6[Store_ID],Table6[Region],"Not Found") -> South Zone 1 | U3: EMP0156 | V3: =_xlfn.XLOOKUP(Table2[[#This Row],[Employee_ID]],Table5[Employee_ID],Table5[Employee Name],"Not Found") -> Deepthi Iyengar | W3: 2 | X3: 909.55 | Y3: 25 | Z3: 454.77 | AA3: 5 | AB3: 68.22 | AC3: 1432.55 | AD3: 984.22 | AE3: =(AC3-AD3-AB3) -> 380.11 | AF3: Debit Card | AG3: =IFERROR(Table2[[#This Row],[Profit]]/Table2[[#This Row],[Sales Amount]],0) -> 0.26533803 | AH3: =TRIM(Table2[[#This Row],[Payment Modee]]) -> Debit Card | AI3: Online | AJ3: Not Returned | AK3: 13:25 | AL3: =IF(HOUR(Table2[[#This Row],[Order Time]])<12,"Morning",IF(HOUR(Table2[[#This Row],[Order Time]])<17,"Afternoon",IF(HOUR(Table2[[#This Row],[Order Time]])<21,"Evening","Night"))) -> Afternoon | AM3: Weekend
A4: INV100003 | B4: 45657 | C4: =YEAR(Table2[[#This Row],[Invoice Date]]) -> 2024 | D4: =TEXT(Table2[[#This Row],[Invoice Date]],"mmm") -> Dec | E4: =Table2[[#This Row],[Store_ID]]&"-"&Table2[[#This Row],[Year]]&"-"&Table2[[#This Row],[Month]] -> STR011-2024-Dec | F4: CUST0711 | G4: =_xlfn.XLOOKUP(Table2[[#This Row],[Customer_ID]],Table3[Customer_ID],Table3[Customer Name],"Not Found") -> Deepthi Sundaram | H4: =_xlfn.XLOOKUP(Table2[[#This Row],[Customer_ID]],Table3[Customer_ID],Table3[Gender],"Female") -> Female | I4: =_xlfn.XLOOKUP(Table2[[#This Row],[Customer_ID]],Table3[Customer_ID],Table3[City],"Missing Memebership") -> Nellore | J4: =_xlfn.XLOOKUP(Table2[[#This Row],[Customer_ID]],Table3[Customer_ID],Table3[State],"Karnataka") -> Andhra Pradesh | K4: =_xlfn.XLOOKUP(Table2[[#This Row],[Customer_ID]],Table3[Customer_ID],Table3[Membership],"Regular") -> Silver | L4: PRD0065 | M4: =_xlfn.XLOOKUP(Table2[[#This Row],[Product_ID]],Table4[Product_ID],Table4[Product_Name],"Not Found") -> Westside Georgette Saree White | N4: =_xlfn.XLOOKUP(Table2[[#This Row],[Product_ID]],Table4[Product_ID],Table4[Category],"Not Found") -> Women Sarees | O4: =_xlfn.XLOOKUP(Table2[[#This Row],[Product_ID]],Table4[Product_ID],Table4[Subcategory],"Not Found") -> Georgette Saree | P4: =_xlfn.XLOOKUP(Table2[[#This Row],[Product_ID]],Table4[Product_ID],Table4[Brand],"Missing Brand") -> Westside | Q4: STR011 | R4: =_xlfn.XLOOKUP(Table2[[#This Row],[Store_ID]],Table6[Store_ID],Table6[Store Name],"Not Found") -> TrendMart Tirupati Standard | S4: =_xlfn.XLOOKUP(Table2[[#This Row],[Store_ID]],Table6[Store_ID],Table6[Monthly Target],"Missing Target") -> 2000000 | T4: =_xlfn.XLOOKUP(Table2[[#This Row],[Store_ID]],Table6[Store_ID],Table6[Region],"Not Found") -> South Zone 3 | U4: EMP0223 | V4: =_xlfn.XLOOKUP(Table2[[#This Row],[Employee_ID]],Table5[Employee_ID],Table5[Employee Name],"Not Found") -> Meena Krishnan | W4: 2 | X4: 3872.21 | Y4: 0 | Z4: 0 | AA4: 12 | AB4: 929.33 | AC4: 8673.75 | AD4: 5267.12 | AE4: =(AC4-AD4-AB4) -> 2477.3 | AF4: Debit Card | AG4: =IFERROR(Table2[[#This Row],[Profit]]/Table2[[#This Row],[Sales Amount]],0) -> 0.28560888 | AH4: =TRIM(Table2[[#This Row],[Payment Modee]]) -> Debit Card | AI4: Online | AJ4: Not Returned | AK4: 21:10 | AL4: =IF(HOUR(Table2[[#This Row],[Order Time]])<12,"Morning",IF(HOUR(Table2[[#This Row],[Order Time]])<17,"Afternoon",IF(HOUR(Table2[[#This Row],[Order Time]])<21,"Evening","Night"))) -> Night | AM4: Weekday
A5: INV100004 | B5: 45437 | C5: =YEAR(Table2[[#This Row],[Invoice Date]]) -> 2024 | D5: =TEXT(Table2[[#This Row],[Invoice Date]],"mmm") -> May | E5: =Table2[[#This Row],[Store_ID]]&"-"&Table2[[#This Row],[Year]]&"-"&Table2[[#This Row],[Month]] -> STR078-2024-May | F5: CUST0466 | G5: =_xlfn.XLOOKUP(Table2[[#This Row],[Customer_ID]],Table3[Customer_ID],Table3[Customer Name],"Not Found") -> Manoj Varma | H5: =_xlfn.XLOOKUP(Table2[[#This Row],[Customer_ID]],Table3[Customer_ID],Table3[Gender],"Female") -> Male | I5: =_xlfn.XLOOKUP(Table2[[#This Row],[Customer_ID]],Table3[Customer_ID],Table3[City],"Missing Memebership") -> Vellore | J5: =_xlfn.XLOOKUP(Table2[[#This Row],[Customer_ID]],Table3[Customer_ID],Table3[State],"Karnataka") -> Tamil Nadu | K5: =_xlfn.XLOOKUP(Table2[[#This Row],[Customer_ID]],Table3[Customer_ID],Table3[Membership],"Regular") -> Regular | L5: PRD0224 | M5: =_xlfn.XLOOKUP(Table2[[#This Row],[Product_ID]],Table4[Product_ID],Table4[Product_Name],"Not Found") -> Max Fashion Printed Saree Brown | N5: =_xlfn.XLOOKUP(Table2[[#This Row],[Product_ID]],Table4[Product_ID],Table4[Category],"Not Found") -> Women Sarees | O5: =_xlfn.XLOOKUP(Table2[[#This Row],[Product_ID]],Table4[Product_ID],Table4[Subcategory],"Not Found") -> Printed Saree | P5: =_xlfn.XLOOKUP(Table2[[#This Row],[Product_ID]],Table4[Product_ID],Table4[Brand],"Missing Brand") -> Max Fashion | Q5: STR078 | R5: =_xlfn.XLOOKUP(Table2[[#This Row],[Store_ID]],Table6[Store_ID],Table6[Store Name],"Not Found") -> TrendMart Vellore Standard | S5: =_xlfn.XLOOKUP(Table2[[#This Row],[Store_ID]],Table6[Store_ID],Table6[Monthly Target],"Missing Target") -> 1200000 | T5: =_xlfn.XLOOKUP(Table2[[#This Row],[Store_ID]],Table6[Store_ID],Table6[Region],"Not Found") -> South Zone 1 | U5: EMP0170 | V5: =_xlfn.XLOOKUP(Table2[[#This Row],[Employee_ID]],Table5[Employee_ID],Table5[Employee Name],"Not Found") -> Jyothi Prasad | W5: 4 | X5: 4857.75 | Y5: 20 | Z5: 3886.2 | AA5: 12 | AB5: 1865.38 | AC5: 17410.18 | AD5: 13483.2 | AE5: =(AC5-AD5-AB5) -> 2061.6 | AF5: UPI | AG5: =IFERROR(Table2[[#This Row],[Profit]]/Table2[[#This Row],[Sales Amount]],0) -> 0.11841348 | AH5: =TRIM(Table2[[#This Row],[Payment Modee]]) -> UPI | AI5: Online | AJ5: Not Returned | AK5: 13:45 | AL5: =IF(HOUR(Table2[[#This Row],[Order Time]])<12,"Morning",IF(HOUR(Table2[[#This Row],[Order Time]])<17,"Afternoon",IF(HOUR(Table2[[#This Row],[Order Time]])<21,"Evening","Night"))) -> Afternoon | AM5: Weekend
A6: INV100005 | B6: 45487 | C6: =YEAR(Table2[[#This Row],[Invoice Date]]) -> 2024 | D6: =TEXT(Table2[[#This Row],[Invoice Date]],"mmm") -> Jul | E6: =Table2[[#This Row],[Store_ID]]&"-"&Table2[[#This Row],[Year]]&"-"&Table2[[#This Row],[Month]] -> STR058-2024-Jul | F6: CUST0406 | G6: =_xlfn.XLOOKUP(Table2[[#This Row],[Customer_ID]],Table3[Customer_ID],Table3[Customer Name],"Not Found") -> Gayathri Srinivasan | H6: =_xlfn.XLOOKUP(Table2[[#This Row],[Customer_ID]],Table3[Customer_ID],Table3[Gender],"Female") -> Female | I6: =_xlfn.XLOOKUP(Table2[[#This Row],[Customer_ID]],Table3[Customer_ID],Table3[City],"Missing Memebership") -> Vijayawada | J6: =_xlfn.XLOOKUP(Table2[[#This Row],[Customer_ID]],Table3[Customer_ID],Table3[State],"Karnataka") -> Andhra Pradesh | K6: =_xlfn.XLOOKUP(Table2[[#This Row],[Customer_ID]],Table3[Customer_ID],Table3[Membership],"Regular") -> Regular | L6: PRD0035 | M6: =_xlfn.XLOOKUP(Table2[[#This Row],[Product_ID]],Table4[Product_ID],Table4[Product_Name],"Not Found") -> Reebok Printed Kurti Wine | N6: =_xlfn.XLOOKUP(Table2[[#This Row],[Product_ID]],Table4[Product_ID],Table4[Category],"Not Found") -> Women Kurtis | O6: =_xlfn.XLOOKUP(Table2[[#This Row],[Product_ID]],Table4[Product_ID],Table4[Subcategory],"Not Found") -> Printed Kurti | P6: =_xlfn.XLOOKUP(Table2[[#This Row],[Product_ID]],Table4[Product_ID],Table4[Brand],"Missing Brand") -> Reebok | Q6: STR058 | R6: =_xlfn.XLOOKUP(Table2[[#This Row],[Store_ID]],Table6[Store_ID],Table6[Store Name],"Not Found") -> TrendMart Thoothukudi Flagship | S6: =_xlfn.XLOOKUP(Table2[[#This Row],[Store_ID]],Table6[Store_ID],Table6[Monthly Target],"Missing Target") -> 1200000 | T6: =_xlfn.XLOOKUP(Table2[[#This Row],[Store_ID]],Table6[Store_ID],Table6[Region],"Not Found") -> South Zone 1 | U6: EMP0090 | V6: =_xlfn.XLOOKUP(Table2[[#This Row],[Employee_ID]],Table5[Employee_ID],Table5[Employee Name],"Not Found") -> Padma Gounder | W6: 1 | X6: 874.25 | Y6: 0 | Z6: 0 | AA6: 5 | AB6: 43.71 | AC6: 917.96 | AD6: 539.76 | AE6: =(AC6-AD6-AB6) -> 334.49 | AF6: Credit Card | AG6: =IFERROR(Table2[[#This Row],[Profit]]/Table2[[#This Row],[Sales Amount]],0) -> 0.36438407 | AH6: =TRIM(Table2[[#This Row],[Payment Modee]]) -> Credit Card | AI6: Offline | AJ6: Not Returned | AK6: 21:11 | AL6: =IF(HOUR(Table2[[#This Row],[Order Time]])<12,"Morning",IF(HOUR(Table2[[#This Row],[Order Time]])<17,"Afternoon",IF(HOUR(Table2[[#This Row],[Order Time]])<21,"Evening","Night"))) -> Night | AM6: Weekend
A7: INV100006 | B7: 45704 | C7: =YEAR(Table2[[#This Row],[Invoice Date]]) -> 2025 | D7: =TEXT(Table2[[#This Row],[Invoice Date]],"mmm") -> Feb | E7: =Table2[[#This Row],[Store_ID]]&"-"&Table2[[#This Row],[Year]]&"-"&Table2[[#This Row],[Month]] -> STR074-2025-Feb | F7: CUST0084 | G7: =_xlfn.XLOOKUP(Table2[[#This Row],[Customer_ID]],Table3[Customer_ID],Table3[Customer Name],"Not Found") -> Hari Kamath | H7: =_xlfn.XLOOKUP(Table2[[#This Row],[Customer_ID]],Table3[Customer_ID],Table3[Gender],"Female") -> Male | I7: =_xlfn.XLOOKUP(Table2[[#This Row],[Customer_ID]],Table3[Customer_ID],Table3[City],"Missing Memebership") -> Tirupati | J7: =_xlfn.XLOOKUP(Table2[[#This Row],[Customer_ID]],Table3[Customer_ID],Table3[State],"Karnataka") -> Andhra Pradesh | K7: =_xlfn.XLOOKUP(Table2[[#This Row],[Customer_ID]],Table3[Customer_ID],Table3[Membership],"Regular") -> Platinum | L7: PRD0199 | M7: =_xlfn.XLOOKUP(Table2[[#This Row],[Product_ID]],Table4[Product_ID],Table4[Product_Name],"Not Found") -> US Polo Assn Formal Shoes Red | N7: =_xlfn.XLOOKUP(Table2[[#This Row],[Product_ID]],Table4[Product_ID],Table4[Category],"Not Found") -> Footwear | O7: =_xlfn.XLOOKUP(Table2[[#This Row],[Product_ID]],Table4[Product_ID],Table4[Subcategory],"Not Found") -> Formal Shoes | P7: =_xlfn.XLOOKUP(Table2[[#This Row],[Product_ID]],Table4[Product_ID],Table4[Brand],"Missing Brand") -> US Polo Assn | Q7: STR074 | R7: =_xlfn.XLOOKUP(Table2[[#This Row],[Store_ID]],Table6[Store_ID],Table6[Store Name],"Not Found") -> TrendMart Kurnool High Street | S7: =_xlfn.XLOOKUP(Table2[[#This Row],[Store_ID]],Table6[Store_ID],Table6[Monthly Target],"Missing Target") -> 1200000 | T7: =_xlfn.XLOOKUP(Table2[[#This Row],[Store_ID]],Table6[Store_ID],Table6[Region],"Not Found") -> South Zone 3 | U7: EMP0204 | V7: =_xlfn.XLOOKUP(Table2[[#This Row],[Employee_ID]],Table5[Employee_ID],Table5[Employee Name],"Not Found") -> Rahul Krishnan | W7: 2 | X7: 3390.61 | Y7: 30 | Z7: 2034.37 | AA7: 12 | AB7: 569.62 | AC7: 5316.47 | AD7: 4849.24 | AE7: =(AC7-AD7-AB7) -> -102.39 | AF7: Credit Card | AG7: =IFERROR(Table2[[#This Row],[Profit]]/Table2[[#This Row],[Sales Amount]],0) -> -0.01925902 | AH7: =TRIM(Table2[[#This Row],[Payment Modee]]) -> Credit Card | AI7: Offline | AJ7: Not Returned | AK7: 10:24 | AL7: =IF(HOUR(Table2[[#This Row],[Order Time]])<12,"Morning",IF(HOUR(Table2[[#This Row],[Order Time]])<17,"Afternoon",IF(HOUR(Table2[[#This Row],[Order Time]])<21,"Evening","Night"))) -> Morning | AM7: Weekend
A8: INV100007 | B8: 45457 | C8: =YEAR(Table2[[#This Row],[Invoice Date]]) -> 2024 | D8: =TEXT(Table2[[#This Row],[Invoice Date]],"mmm") -> Jun | E8: =Table2[[#This Row],[Store_ID]]&"-"&Table2[[#This Row],[Year]]&"-"&Table2[[#This Row],[Month]] -> STR062-2024-Jun | F8: CUST0714 | G8: =_xlfn.XLOOKUP(Table2[[#This Row],[Customer_ID]],Table3[Customer_ID],Table3[Customer Name],"Not Found") -> Yamini Srinivasan | H8: =_xlfn.XLOOKUP(Table2[[#This Row],[Customer_ID]],Table3[Customer_ID],Table3[Gender],"Female") -> Female | I8: =_xlfn.XLOOKUP(Table2[[#This Row],[Customer_ID]],Table3[Customer_ID],Table3[City],"Missing Memebership") -> Alappuzha | J8: =_xlfn.XLOOKUP(Table2[[#This Row],[Customer_ID]],Table3[Customer_ID],Table3[State],"Karnataka") -> Kerala | K8: =_xlfn.XLOOKUP(Table2[[#This Row],[Customer_ID]],Table3[Customer_ID],Table3[Membership],"Regular") -> Silver | L8: PRD0040 | M8: =_xlfn.XLOOKUP(Table2[[#This Row],[Product_ID]],Table4[Product_ID],Table4[Product_Name],"Not Found") -> US Polo Assn Track Suit Maroon | N8: =_xlfn.XLOOKUP(Table2[[#This Row],[Product_ID]],Table4[Product_ID],Table4[Category],"Not Found") -> Sportswear | O8: =_xlfn.XLOOKUP(Table2[[#This Row],[Product_ID]],Table4[Product_ID],Table4[Subcategory],"Not Found") -> Track Suit | P8: =_xlfn.XLOOKUP(Table2[[#This Row],[Product_ID]],Table4[Product_ID],Table4[Brand],"Missing Brand") -> US Polo Assn | Q8: STR062 | R8: =_xlfn.XLOOKUP(Table2[[#This Row],[Store_ID]],Table6[Store_ID],Table6[Store Name],"Not Found") -> TrendMart Vijayawada Standard | S8: =_xlfn.XLOOKUP(Table2[[#This Row],[Store_ID]],Table6[Store_ID],Table6[Monthly Target],"Missing Target") -> 1000000 | T8: =_xlfn.XLOOKUP(Table2[[#This Row],[Store_ID]],Table6[Store_ID],Table6[Region],"Not Found") -> South Zone 3 | U8: EMP0215 | V8: =_xlfn.XLOOKUP(Table2[[#This Row],[Employee_ID]],Table5[Employee_ID],Table5[Employee Name],"Not Found") -> Praveen Gupta | W8: 4 | X8: 1474.99 | Y8: 0 | Z8: 0 | AA8: 12 | AB8: 708 | AC8: 6607.96 | AD8: 4594.64 | AE8: =(AC8-AD8-AB8) -> 1305.32 | AF8: Cash | AG8: =IFERROR(Table2[[#This Row],[Profit]]/Table2[[#This Row],[Sales Amount]],0) -> 0.19753752 | AH8: =TRIM(Table2[[#This Row],[Payment Modee]]) -> Cash | AI8: Offline | AJ8: Not Returned | AK8: 20:20 | AL8: =IF(HOUR(Table2[[#This Row],[Order Time]])<12,"Morning",IF(HOUR(Table2[[#This Row],[Order Time]])<17,"Afternoon",IF(HOUR(Table2[[#This Row],[Order Time]])<21,"Evening","Night"))) -> Evening | AM8: Weekday
A9: INV100008 | B9: 45678 | C9: =YEAR(Table2[[#This Row],[Invoice Date]]) -> 2025 | D9: =TEXT(Table2[[#This Row],[Invoice Date]],"mmm") -> Jan | E9: =Table2[[#This Row],[Store_ID]]&"-"&Table2[[#This Row],[Year]]&"-"&Table2[[#This Row],[Month]] -> STR084-2025-Jan | F9: CUST0121 | G9: =_xlfn.XLOOKUP(Table2[[#This Row],[Customer_ID]],Table3[Customer_ID],Table3[Customer Name],"Not Found") -> Srinivas Prasad | H9: =_xlfn.XLOOKUP(Table2[[#This Row],[Customer_ID]],Table3[Customer_ID],Table3[Gender],"Female") -> Male | I9: =_xlfn.XLOOKUP(Table2[[#This Row],[Customer_ID]],Table3[Customer_ID],Table3[City],"Missing Memebership") -> Kannur | J9: =_xlfn.XLOOKUP(Table2[[#This Row],[Customer_ID]],Table3[Customer_ID],Table3[State],"Karnataka") -> Kerala | K9: =_xlfn.XLOOKUP(Table2[[#This Row],[Customer_ID]],Table3[Customer_ID],Table3[Membership],"Regular") -> Silver | L9: PRD0196 | M9: =_xlfn.XLOOKUP(Table2[[#This Row],[Product_ID]],Table4[Product_ID],Table4[Product_Name],"Not Found") -> Metro Shoes Slim Fit Wine | N9: =_xlfn.XLOOKUP(Table2[[#This Row],[Product_ID]],Table4[Product_ID],Table4[Category],"Not Found") -> Men Jeans | O9: =_xlfn.XLOOKUP(Table2[[#This Row],[Product_ID]],Table4[Product_ID],Table4[Subcategory],"Not Found") -> Slim Fit | P9: =_xlfn.XLOOKUP(Table2[[#This Row],[Product_ID]],Table4[Product_ID],Table4[Brand],"Missing Brand") -> Metro Shoes | Q9: STR084 | R9: =_xlfn.XLOOKUP(Table2[[#This Row],[Store_ID]],Table6[Store_ID],Table6[Store Name],"Not Found") -> TrendMart Tirupati High Street | S9: =_xlfn.XLOOKUP(Table2[[#This Row],[Store_ID]],Table6[Store_ID],Table6[Monthly Target],"Missing Target") -> 2000000 | T9: =_xlfn.XLOOKUP(Table2[[#This Row],[Store_ID]],Table6[Store_ID],Table6[Region],"Not Found") -> South Zone 3 | U9: EMP0285 | V9: =_xlfn.XLOOKUP(Table2[[#This Row],[Employee_ID]],Table5[Employee_ID],Table5[Employee Name],"Not Found") -> Chandran Krishnan | W9: 1 | X9: 1407.12 | Y9: 0 | Z9: 0 | AA9: 12 | AB9: 168.85 | AC9: 1575.97 | AD9: 1067.72 | AE9: =(AC9-AD9-AB9) -> 339.4 | AF9: UPI | AG9: =IFERROR(Table2[[#This Row],[Profit]]/Table2[[#This Row],[Sales Amount]],0) -> 0.21535943 | AH9: =TRIM(Table2[[#This Row],[Payment Modee]]) -> UPI | AI9: Offline | AJ9: Not Returned | AK9: 21:28 | AL9: =IF(HOUR(Table2[[#This Row],[Order Time]])<12,"Morning",IF(HOUR(Table2[[#This Row],[Order Time]])<17,"Afternoon",IF(HOUR(Table2[[#This Row],[Order Time]])<21,"Evening","Night"))) -> Night | AM9: Weekday
A10: INV100009 | B10: 45541 | C10: =YEAR(Table2[[#This Row],[Invoice Date]]) -> 2024 | D10: =TEXT(Table2[[#This Row],[Invoice Date]],"mmm") -> Sep | E10: =Table2[[#This Row],[Store_ID]]&"-"&Table2[[#This Row],[Year]]&"-"&Table2[[#This Row],[Month]] -> STR021-2024-Sep | F10: CUST0782 | G10: =_xlfn.XLOOKUP(Table2[[#This Row],[Customer_ID]],Table3[Customer_ID],Table3[Customer Name],"Not Found") -> Rahul Yadav | H10: =_xlfn.XLOOKUP(Table2[[#This Row],[Customer_ID]],Table3[Customer_ID],Table3[Gender],"Female") -> Male | I10: =_xlfn.XLOOKUP(Table2[[#This Row],[Customer_ID]],Table3[Customer_ID],Table3[City],"Missing Memebership") -> Alappuzha | J10: =_xlfn.XLOOKUP(Table2[[#This Row],[Customer_ID]],Table3[Customer_ID],Table3[State],"Karnataka") -> Kerala | K10: =_xlfn.XLOOKUP(Table2[[#This Row],[Customer_ID]],Table3[Customer_ID],Table3[Membership],"Regular") -> Gold | L10: PRD0114 | M10: =_xlfn.XLOOKUP(Table2[[#This Row],[Product_ID]],Table4[Product_ID],Table4[Product_Name],"Not Found") -> Arrow Sunglasses Red | N10: =_xlfn.XLOOKUP(Table2[[#This Row],[Product_ID]],Table4[Product_ID],Table4[Category],"Not Found") -> Accessories | O10: =_xlfn.XLOOKUP(Table2[[#This Row],[Product_ID]],Table4[Product_ID],Table4[Subcategory],"Not Found") -> Sunglasses | P10: =_xlfn.XLOOKUP(Table2[[#This Row],[Product_ID]],Table4[Product_ID],Table4[Brand],"Missing Brand") -> Arrow | Q10: STR021 | R10: =_xlfn.XLOOKUP(Table2[[#This Row],[Store_ID]],Table6[Store_ID],Table6[Store Name],"Not Found") -> TrendMart Kozhikode Standard | S10: =_xlfn.XLOOKUP(Table2[[#This Row],[Store_ID]],Table6[Store_ID],Table6[Monthly Target],"Missing Target") -> 2000000 | T10: =_xlfn.XLOOKUP(Table2[[#This Row],[Store_ID]],Table6[Store_ID],Table6[Region],"Not Found") -> South Zone 1 | U10: EMP0001 | V10: =_xlfn.XLOOKUP(Table2[[#This Row],[Employee_ID]],Table5[Employee_ID],Table5[Employee Name],"Not Found") -> Charulatha Kumar | W10: 5 | X10: 851.61 | Y10: 5 | Z10: 212.9 | AA10: 5 | AB10: 202.26 | AC10: 4247.41 | AD10: 2443 | AE10: =(AC10-AD10-AB10) -> 1602.15 | AF10: Debit Card | AG10: =IFERROR(Table2[[#This Row],[Profit]]/Table2[[#This Row],[Sales Amount]],0) -> 0.37720634 | AH10: =TRIM(Table2[[#This Row],[Payment Modee]]) -> Debit Card | AI10: Offline | AJ10: Not Returned | AK10: 19:05 | AL10: =IF(HOUR(Table2[[#This Row],[Order Time]])<12,"Morning",IF(HOUR(Table2[[#This Row],[Order Time]])<17,"Afternoon",IF(HOUR(Table2[[#This Row],[Order Time]])<21,"Evening","Night"))) -> Evening | AM10: Weekday
A11: INV100010 | B11: 45583 | C11: =YEAR(Table2[[#This Row],[Invoice Date]]) -> 2024 | D11: =TEXT(Table2[[#This Row],[Invoice Date]],"mmm") -> Oct | E11: =Table2[[#This Row],[Store_ID]]&"-"&Table2[[#This Row],[Year]]&"-"&Table2[[#This Row],[Month]] -> STR085-2024-Oct | F11: CUST0429 | G11: =_xlfn.XLOOKUP(Table2[[#This Row],[Customer_ID]],Table3[Customer_ID],Table3[Customer Name],"Not Found") -> Nandini Gopalakrishnan | H11: =_xlfn.XLOOKUP(Table2[[#This Row],[Customer_ID]],Table3[Customer_ID],Table3[Gender],"Female") -> Female | I11: =_xlfn.XLOOKUP(Table2[[#This Row],[Customer_ID]],Table3[Customer_ID],Table3[City],"Missing Memebership") -> Vellore | J11: =_xlfn.XLOOKUP(Table2[[#This Row],[Customer_ID]],Table3[Customer_ID],Table3[State],"Karnataka") -> Tamil Nadu | K11: =_xlfn.XLOOKUP(Table2[[#This Row],[Customer_ID]],Table3[Customer_ID],Table3[Membership],"Regular") -> Regular | L11: PRD0075 | M11: =_xlfn.XLOOKUP(Table2[[#This Row],[Product_ID]],Table4[Product_ID],Table4[Product_Name],"Not Found") -> Sonata Bootcut Navy Blue | N11: =_xlfn.XLOOKUP(Table2[[#This Row],[Product_ID]],Table4[Product_ID],Table4[Category],"Not Found") -> Women Jeans | O11: =_xlfn.XLOOKUP(Table2[[#This Row],[Product_ID]],Table4[Product_ID],Table4[Subcategory],"Not Found") -> Bootcut | P11: =_xlfn.XLOOKUP(Table2[[#This Row],[Product_ID]],Table4[Product_ID],Table4[Brand],"Missing Brand") -> Sonata | Q11: STR085 | R11: =_xlfn.XLOOKUP(Table2[[#This Row],[Store_ID]],Table6[Store_ID],Table6[Store Name],"Not Found") -> TrendMart Nizamabad Outlet | S11: =_xlfn.XLOOKUP(Table2[[#This Row],[Store_ID]],Table6[Store_ID],Table6[Monthly Target],"Missing Target") -> 1500000 | T11: =_xlfn.XLOOKUP(Table2[[#This Row],[Store_ID]],Table6[Store_ID],Table6[Region],"Not Found") -> South Zone 2 | U11: EMP0090 | V11: =_xlfn.XLOOKUP(Table2[[#This Row],[Employee_ID]],Table5[Employee_ID],Table5[Employee Name],"Not Found") -> Padma Gounder | W11: 1 | X11: 1041.15 | Y11: 0 | Z11: 0 | AA11: 12 | AB11: 124.94 | AC11: 1166.09 | AD11: 692.53 | AE11: =(AC11-AD11-AB11) -> 348.62 | AF11: Credit Card | AG11: =IFERROR(Table2[[#This Row],[Profit]]/Table2[[#This Row],[Sales Amount]],0) -> 0.29896492 | AH11: =TRIM(Table2[[#This Row],[Payment Modee]]) -> Credit Card | AI11: Offline | AJ11: Not Returned | AK11: 10:34 | AL11: =IF(HOUR(Table2[[#This Row],[Order Time]])<12,"Morning",IF(HOUR(Table2[[#This Row],[Order Time]])<17,"Afternoon",IF(HOUR(Table2[[#This Row],[Order Time]])<21,"Evening","Night"))) -> Morning | AM11: Weekday
A12: INV100011 | B12: 45677 | C12: =YEAR(Table2[[#This Row],[Invoice Date]]) -> 2025 | D12: =TEXT(Table2[[#This Row],[Invoice Date]],"mmm") -> Jan | E12: =Table2[[#This Row],[Store_ID]]&"-"&Table2[[#This Row],[Year]]&"-"&Table2[[#This Row],[Month]] -> STR004-2025-Jan | F12: CUST0162 | G12: =_xlfn.XLOOKUP(Table2[[#This Row],[Customer_ID]],Table3[Customer_ID],Table3[Customer Name],"Not Found") -> Tanvi Balasubramaniam | H12: =_xlfn.XLOOKUP(Table2[[#This Row],[Customer_ID]],Table3[Customer_ID],Table3[Gender],"Female") -> Female | I12: =_xlfn.XLOOKUP(Table2[[#This Row],[Customer_ID]],Table3[Customer_ID],Table3[City],"Missing Memebership") -> Kannur | J12: =_xlfn.XLOOKUP(Table2[[#This Row],[Customer_ID]],Table3[Customer_ID],Table3[State],"Karnataka") -> Kerala | K12: =_xlfn.XLOOKUP(Table2[[#This Row],[Customer_ID]],Table3[Customer_ID],Table3[Membership],"Regular") -> Silver | L12: PRD0117 | M12: =_xlfn.XLOOKUP(Table2[[#This Row],[Product_ID]],Table4[Product_ID],Table4[Product_Name],"Not Found") -> Nike Shirt Dress Peach | N12: =_xlfn.XLOOKUP(Table2[[#This Row],[Product_ID]],Table4[Product_ID],Table4[Category],"Not Found") -> Women Dresses | O12: =_xlfn.XLOOKUP(Table2[[#This Row],[Product_ID]],Table4[Product_ID],Table4[Subcategory],"Not Found") -> Shirt Dress | P12: =_xlfn.XLOOKUP(Table2[[#This Row],[Product_ID]],Table4[Product_ID],Table4[Brand],"Missing Brand") -> Nike | Q12: STR004 | R12: =_xlfn.XLOOKUP(Table2[[#This Row],[Store_ID]],Table6[Store_ID],Table6[Store Name],"Not Found") -> TrendMart Kalaburagi Mall Kiosk | S12: =_xlfn.XLOOKUP(Table2[[#This Row],[Store_ID]],Table6[Store_ID],Table6[Monthly Target],"Missing Target") -> 800000 | T12: =_xlfn.XLOOKUP(Table2[[#This Row],[Store_ID]],Table6[Store_ID],Table6[Region],"Not Found") -> South Zone 2 | U12: EMP0258 | V12: =_xlfn.XLOOKUP(Table2[[#This Row],[Employee_ID]],Table5[Employee_ID],Table5[Employee Name],"Not Found") -> Preethi Singh | W12: 4 | X12: 1761.12 | Y12: 10 | Z12: 704.45 | AA12: 12 | AB12: 760.8 | AC12: 7100.83 | AD12: 5599.4 | AE12: =(AC12-AD12-AB12) -> 740.63 | AF12: Credit Card | AG12: =IFERROR(Table2[[#This Row],[Profit]]/Table2[[#This Row],[Sales Amount]],0) -> 0.10430189 | AH12: =TRIM(Table2[[#This Row],[Payment Modee]]) -> Credit Card | AI12: Offline | AJ12: Not Returned | AK12: 13:20 | AL12: =IF(HOUR(Table2[[#This Row],[Order Time]])<12,"Morning",IF(HOUR(Table2[[#This Row],[Order Time]])<17,"Afternoon",IF(HOUR(Table2[[#This Row],[Order Time]])<21,"Evening","Night"))) -> Afternoon | AM12: Weekday
A13: INV100012 | B13: 45736 | C13: =YEAR(Table2[[#This Row],[Invoice Date]]) -> 2025 | D13: =TEXT(Table2[[#This Row],[Invoice Date]],"mmm") -> Mar | E13: =Table2[[#This Row],[Store_ID]]&"-"&Table2[[#This Row],[Year]]&"-"&Table2[[#This Row],[Month]] -> STR068-2025-Mar | F13: CUST0794 | G13: =_xlfn.XLOOKUP(Table2[[#This Row],[Customer_ID]],Table3[Customer_ID],Table3[Customer Name],"Not Found") -> Rahul Gupta | H13: =_xlfn.XLOOKUP(Table2[[#This Row],[Customer_ID]],Table3[Customer_ID],Table3[Gender],"Female") -> Male | I13: =_xlfn.XLOOKUP(Table2[[#This Row],[Customer_ID]],Table3[Customer_ID],Table3[City],"Missing Memebership") -> Chennai | J13: =_xlfn.XLOOKUP(Table2[[#This Row],[Customer_ID]],Table3[Customer_ID],Table3[State],"Karnataka") -> Tamil Nadu | K13: =_xlfn.XLOOKUP(Table2[[#This Row],[Customer_ID]],Table3[Customer_ID],Table3[Membership],"Regular") -> Silver | L13: PRD0078 | M13: =_xlfn.XLOOKUP(Table2[[#This Row],[Product_ID]],Table4[Product_ID],Table4[Product_Name],"Not Found") -> Metro Shoes Regular Fit Charcoal | N13: =_xlfn.XLOOKUP(Table2[[#This Row],[Product_ID]],Table4[Product_ID],Table4[Category],"Not Found") -> Men Jeans | O13: =_xlfn.XLOOKUP(Table2[[#This Row],[Product_ID]],Table4[Product_ID],Table4[Subcategory],"Not Found") -> Regular Fit | P13: =_xlfn.XLOOKUP(Table2[[#This Row],[Product_ID]],Table4[Product_ID],Table4[Brand],"Missing Brand") -> Metro Shoes | Q13: STR068 | R13: =_xlfn.XLOOKUP(Table2[[#This Row],[Store_ID]],Table6[Store_ID],Table6[Store Name],"Not Found") -> TrendMart Madurai Mall Kiosk | S13: =_xlfn.XLOOKUP(Table2[[#This Row],[Store_ID]],Table6[Store_ID],Table6[Monthly Target],"Missing Target") -> 2000000 | T13: =_xlfn.XLOOKUP(Table2[[#This Row],[Store_ID]],Table6[Store_ID],Table6[Region],"Not Found") -> South Zone 1 | U13: EMP0204 | V13: =_xlfn.XLOOKUP(Table2[[#This Row],[Employee_ID]],Table5[Employee_ID],Table5[Employee Name],"Not Found") -> Rahul Krishnan | W13: 1 | X13: 1019.42 | Y13: 5 | Z13: 50.97 | AA13: 12 | AB13: 116.21 | AC13: 1084.66 | AD13: 828.44 | AE13: =(AC13-AD13-AB13) -> 140.01 | AF13: UPI | AG13: =IFERROR(Table2[[#This Row],[Profit]]/Table2[[#This Row],[Sales Amount]],0) -> 0.12908192 | AH13: =TRIM(Table2[[#This Row],[Payment Modee]]) -> UPI | AI13: Online | AJ13: Not Returned | AK13: 18:28 | AL13: =IF(HOUR(Table2[[#This Row],[Order Time]])<12,"Morning",IF(HOUR(Table2[[#This Row],[Order Time]])<17,"Afternoon",IF(HOUR(Table2[[#This Row],[Order Time]])<21,"Evening","Night"))) -> Evening | AM13: Weekday
... A68: INV100067 | B68: 45622 | C68: =YEAR(Table2[[#This Row],[Invoice Date]]) -> 2024 | D68: =TEXT(Table2[[#This Row],[Invoice Date]],"mmm") -> Nov | E68: =Table2[[#This Row],[Store_ID]]&"-"&Table2[[#This Row],[Year]]&"-"&Table2[[#This Row],[Month]] -> STR100-2024-Nov | F68: CUST0746 | G68: =_xlfn.XLOOKUP(Table2[[#This Row],[Customer_ID]],Table3[Customer_ID],Table3[Customer Name],"Not Found") -> Pandian Venkatesan | H68: =_xlfn.XLOOKUP(Table2[[#This Row],[Customer_ID]],Table3[Customer_ID],Table3[Gender],"Female") -> Male | I68: =_xlfn.XLOOKUP(Table2[[#This Row],[Customer_ID]],Table3[Customer_ID],Table3[City],"Missing Memebership") -> Kalaburagi | J68: =_xlfn.XLOOKUP(Table2[[#This Row],[Customer_ID]],Table3[Customer_ID],Table3[State],"Karnataka") -> Karnataka | K68: =_xlfn.XLOOKUP(Table2[[#This Row],[Customer_ID]],Table3[Customer_ID],Table3[Membership],"Regular") -> Silver | L68: PRD0019 | M68: =_xlfn.XLOOKUP(Table2[[#This Row],[Product_ID]],Table4[Product_ID],Table4[Product_Name],"Not Found") -> Sonata Girls Frock Cream | N68: =_xlfn.XLOOKUP(Table2[[#This Row],[Product_ID]],Table4[Product_ID],Table4[Category],"Not Found") -> Kids Wear | O68: =_xlfn.XLOOKUP(Table2[[#This Row],[Product_ID]],Table4[Product_ID],Table4[Subcategory],"Not Found") -> Kids T-Shirt | P68: =_xlfn.XLOOKUP(Table2[[#This Row],[Product_ID]],Table4[Product_ID],Table4[Brand],"Missing Brand") -> Jack & Jones | Q68: STR100 | R68: =_xlfn.XLOOKUP(Table2[[#This Row],[Store_ID]],Table6[Store_ID],Table6[Store Name],"Not Found") -> TrendMart Hubballi Standard | S68: =_xlfn.XLOOKUP(Table2[[#This Row],[Store_ID]],Table6[Store_ID],Table6[Monthly Target],"Missing Target") -> 2500000 | T68: =_xlfn.XLOOKUP(Table2[[#This Row],[Store_ID]],Table6[Store_ID],Table6[Region],"Not Found") -> South Zone 2 | U68: EMP0141 | V68: =_xlfn.XLOOKUP(Table2[[#This Row],[Employee_ID]],Table5[Employee_ID],Table5[Employee Name],"Not Found") -> Dhruv Mishra | W68: 1 | X68: 640.02 | Y68: 25 | Z68: 160 | AA68: 5 | AB68: 24 | AC68: 504.02 | AD68: 413.39 | AE68: =(AC68-AD68-AB68) -> 66.63 | AF68: Cash | AG68: =IFERROR(Table2[[#This Row],[Profit]]/Table2[[#This Row],[Sales Amount]],0) -> 0.13219714 | AH68: =TRIM(Table2[[#This Row],[Payment Modee]]) -> Cash | AI68: Online | AJ68: Not Returned | AK68: 16:30 | AL68: =IF(HOUR(Table2[[#This Row],[Order Time]])<12,"Morning",IF(HOUR(Table2[[#This Row],[Order Time]])<17,"Afternoon",IF(HOUR(Table2[[#This Row],[Order Time]])<21,"Evening","Night"))) -> Afternoon | AM68: Weekday
A69: INV100068 | B69: 45541 | C69: =YEAR(Table2[[#This Row],[Invoice Date]]) -> 2024 | D69: =TEXT(Table2[[#This Row],[Invoice Date]],"mmm") -> Sep | E69: =Table2[[#This Row],[Store_ID]]&"-"&Table2[[#This Row],[Year]]&"-"&Table2[[#This Row],[Month]] -> STR112-2024-Sep | F69: CUST0583 | G69: =_xlfn.XLOOKUP(Table2[[#This Row],[Customer_ID]],Table3[Customer_ID],Table3[Customer Name],"Not Found") -> Feroz Naicker | H69: =_xlfn.XLOOKUP(Table2[[#This Row],[Customer_ID]],Table3[Customer_ID],Table3[Gender],"Female") -> Male | I69: =_xlfn.XLOOKUP(Table2[[#This Row],[Customer_ID]],Table3[Customer_ID],Table3[City],"Missing Memebership") -> Guntur | J69: =_xlfn.XLOOKUP(Table2[[#This Row],[Customer_ID]],Table3[Customer_ID],Table3[State],"Karnataka") -> Andhra Pradesh | K69: =_xlfn.XLOOKUP(Table2[[#This Row],[Customer_ID]],Table3[Customer_ID],Table3[Membership],"Regular") -> Silver | L69: PRD0134 | M69: =_xlfn.XLOOKUP(Table2[[#This Row],[Product_ID]],Table4[Product_ID],Table4[Product_Name],"Not Found") -> Jack & Jones Maxi Dress Maroon | N69: =_xlfn.XLOOKUP(Table2[[#This Row],[Product_ID]],Table4[Product_ID],Table4[Category],"Not Found") -> Women Dresses | O69: =_xlfn.XLOOKUP(Table2[[#This Row],[Product_ID]],Table4[Product_ID],Table4[Subcategory],"Not Found") -> Maxi Dress | P69: =_xlfn.XLOOKUP(Table2[[#This Row],[Product_ID]],Table4[Product_ID],Table4[Brand],"Missing Brand") -> Jack & Jones | Q69: STR112 | R69: =_xlfn.XLOOKUP(Table2[[#This Row],[Store_ID]],Table6[Store_ID],Table6[Store Name],"Not Found") -> TrendMart Guntur Outlet | S69: =_xlfn.XLOOKUP(Table2[[#This Row],[Store_ID]],Table6[Store_ID],Table6[Monthly Target],"Missing Target") -> 1500000 | T69: =_xlfn.XLOOKUP(Table2[[#This Row],[Store_ID]],Table6[Store_ID],Table6[Region],"Not Found") -> South Zone 3 | U69: EMP0203 | V69: =_xlfn.XLOOKUP(Table2[[#This Row],[Employee_ID]],Table5[Employee_ID],Table5[Employee Name],"Not Found") -> Rani Mishra | W69: 0 | X69: 924.29 | Y69: 0 | Z69: 0 | AA69: 5 | AB69: 0 | AC69: 0 | AD69: 0 | AE69: 0 | AF69: EMI | AG69: =IFERROR(Table2[[#This Row],[Profit]]/Table2[[#This Row],[Sales Amount]],0) -> 0 | AH69: =TRIM(Table2[[#This Row],[Payment Modee]]) -> EMI | AI69: Online | AJ69: Not Returned | AK69: 18:42 | AL69: =IF(HOUR(Table2[[#This Row],[Order Time]])<12,"Morning",IF(HOUR(Table2[[#This Row],[Order Time]])<17,"Afternoon",IF(HOUR(Table2[[#This Row],[Order Time]])<21,"Evening","Night"))) -> Evening | AM69: Weekday
A70: INV100069 | B70: 45622 | C70: =YEAR(Table2[[#This Row],[Invoice Date]]) -> 2024 | D70: =TEXT(Table2[[#This Row],[Invoice Date]],"mmm") -> Nov | E70: =Table2[[#This Row],[Store_ID]]&"-"&Table2[[#This Row],[Year]]&"-"&Table2[[#This Row],[Month]] -> STR088-2024-Nov | F70: CUST0422 | G70: =_xlfn.XLOOKUP(Table2[[#This Row],[Customer_ID]],Table3[Customer_ID],Table3[Customer Name],"Not Found") -> Malathi Shetty | H70: =_xlfn.XLOOKUP(Table2[[#This Row],[Customer_ID]],Table3[Customer_ID],Table3[Gender],"Female") -> Female | I70: =_xlfn.XLOOKUP(Table2[[#This Row],[Customer_ID]],Table3[Customer_ID],Table3[City],"Missing Memebership") -> Nellore | J70: =_xlfn.XLOOKUP(Table2[[#This Row],[Customer_ID]],Table3[Customer_ID],Table3[State],"Karnataka") -> Andhra Pradesh | K70: =_xlfn.XLOOKUP(Table2[[#This Row],[Customer_ID]],Table3[Customer_ID],Table3[Membership],"Regular") -> Silver | L70: PRD0117 | M70: =_xlfn.XLOOKUP(Table2[[#This Row],[Product_ID]],Table4[Product_ID],Table4[Product_Name],"Not Found") -> Nike Shirt Dress Peach | N70: =_xlfn.XLOOKUP(Table2[[#This Row],[Product_ID]],Table4[Product_ID],Table4[Category],"Not Found") -> Women Dresses | O70: =_xlfn.XLOOKUP(Table2[[#This Row],[Product_ID]],Table4[Product_ID],Table4[Subcategory],"Not Found") -> Shirt Dress | P70: =_xlfn.XLOOKUP(Table2[[#This Row],[Product_ID]],Table4[Product_ID],Table4[Brand],"Missing Brand") -> Nike | Q70: STR088 | R70: =_xlfn.XLOOKUP(Table2[[#This Row],[Store_ID]],Table6[Store_ID],Table6[Store Name],"Not Found") -> TrendMart Warangal High Street | S70: =_xlfn.XLOOKUP(Table2[[#This Row],[Store_ID]],Table6[Store_ID],Table6[Monthly Target],"Missing Target") -> 2000000 | T70: =_xlfn.XLOOKUP(Table2[[#This Row],[Store_ID]],Table6[Store_ID],Table6[Region],"Not Found") -> South Zone 2 | U70: EMP0204 | V70: =_xlfn.XLOOKUP(Table2[[#This Row],[Employee_ID]],Table5[Employee_ID],Table5[Employee Name],"Not Found") -> Rahul Krishnan | W70: 2 | X70: 1714.04 | Y70: 10 | Z70: 342.81 | AA70: 12 | AB70: 370.23 | AC70: 3455.5 | AD70: 2799.7 | AE70: =(AC70-AD70-AB70) -> 285.57 | AF70: Cash | AG70: =IFERROR(Table2[[#This Row],[Profit]]/Table2[[#This Row],[Sales Amount]],0) -> 0.082642165 | AH70: =TRIM(Table2[[#This Row],[Payment Modee]]) -> Cash | AI70: Online | AJ70: Not Returned | AK70: 19:44 | AL70: =IF(HOUR(Table2[[#This Row],[Order Time]])<12,"Morning",IF(HOUR(Table2[[#This Row],[Order Time]])<17,"Afternoon",IF(HOUR(Table2[[#This Row],[Order Time]])<21,"Evening","Night"))) -> Evening | AM70: Weekday
A71: INV100070 | B71: 45620 | C71: =YEAR(Table2[[#This Row],[Invoice Date]]) -> 2024 | D71: =TEXT(Table2[[#This Row],[Invoice Date]],"mmm") -> Nov | E71: =Table2[[#This Row],[Store_ID]]&"-"&Table2[[#This Row],[Year]]&"-"&Table2[[#This Row],[Month]] -> STR096-2024-Nov | F71: CUST0613 | G71: =_xlfn.XLOOKUP(Table2[[#This Row],[Customer_ID]],Table3[Customer_ID],Table3[Customer Name],"Not Found") -> Usha Krishnan | H71: =_xlfn.XLOOKUP(Table2[[#This Row],[Customer_ID]],Table3[Customer_ID],Table3[Gender],"Female") -> Female | I71: =_xlfn.XLOOKUP(Table2[[#This Row],[Customer_ID]],Table3[Customer_ID],Table3[City],"Missing Memebership") -> Kalaburagi | J71: =_xlfn.XLOOKUP(Table2[[#This Row],[Customer_ID]],Table3[Customer_ID],Table3[State],"Karnataka") -> Karnataka | K71: =_xlfn.XLOOKUP(Table2[[#This Row],[Customer_ID]],Table3[Customer_ID],Table3[Membership],"Regular") -> Gold | L71: PRD0116 | M71: =_xlfn.XLOOKUP(Table2[[#This Row],[Product_ID]],Table4[Product_ID],Table4[Product_Name],"Not Found") -> Woodland Bootcut Peach | N71: =_xlfn.XLOOKUP(Table2[[#This Row],[Product_ID]],Table4[Product_ID],Table4[Category],"Not Found") -> Women Jeans | O71: =_xlfn.XLOOKUP(Table2[[#This Row],[Product_ID]],Table4[Product_ID],Table4[Subcategory],"Not Found") -> Bootcut | P71: =_xlfn.XLOOKUP(Table2[[#This Row],[Product_ID]],Table4[Product_ID],Table4[Brand],"Missing Brand") -> Woodland | Q71: STR096 | R71: =_xlfn.XLOOKUP(Table2[[#This Row],[Store_ID]],Table6[Store_ID],Table6[Store Name],"Not Found") -> TrendMart Mangaluru Mall Kiosk | S71: =_xlfn.XLOOKUP(Table2[[#This Row],[Store_ID]],Table6[Store_ID],Table6[Monthly Target],"Missing Target") -> 1500000 | T71: =_xlfn.XLOOKUP(Table2[[#This Row],[Store_ID]],Table6[Store_ID],Table6[Region],"Not Found") -> South Zone 2 | U71: EMP0215 | V71: =_xlfn.XLOOKUP(Table2[[#This Row],[Employee_ID]],Table5[Employee_ID],Table5[Employee Name],"Not Found") -> Praveen Gupta | W71: 3 | X71: 1579.45 | Y71: 15 | Z71: 710.75 | AA71: 12 | AB71: 483.31 | AC71: 4510.91 | AD71: 3146.13 | AE71: =(AC71-AD71-AB71) -> 881.47 | AF71: Debit Card | AG71: =IFERROR(Table2[[#This Row],[Profit]]/Table2[[#This Row],[Sales Amount]],0) -> 0.19540847 | AH71: =TRIM(Table2[[#This Row],[Payment Modee]]) -> Debit Card | AI71: Online | AJ71: Not Returned | AK71: 21:51 | AL71: =IF(HOUR(Table2[[#This Row],[Order Time]])<12,"Morning",IF(HOUR(Table2[[#This Row],[Order Time]])<17,"Afternoon",IF(HOUR(Table2[[#This Row],[Order Time]])<21,"Evening","Night"))) -> Night | AM71: Weekend
A72: INV100071 | B72: 45426 | C72: =YEAR(Table2[[#This Row],[Invoice Date]]) -> 2024 | D72: =TEXT(Table2[[#This Row],[Invoice Date]],"mmm") -> May | E72: =Table2[[#This Row],[Store_ID]]&"-"&Table2[[#This Row],[Year]]&"-"&Table2[[#This Row],[Month]] -> STR016-2024-May | F72: CUST0131 | G72: =_xlfn.XLOOKUP(Table2[[#This Row],[Customer_ID]],Table3[Customer_ID],Table3[Customer Name],"Not Found") -> Jyothi Achari | H72: =_xlfn.XLOOKUP(Table2[[#This Row],[Customer_ID]],Table3[Customer_ID],Table3[Gender],"Female") -> Female | I72: =_xlfn.XLOOKUP(Table2[[#This Row],[Customer_ID]],Table3[Customer_ID],Table3[City],"Missing Memebership") -> Tiruchirappalli | J72: =_xlfn.XLOOKUP(Table2[[#This Row],[Customer_ID]],Table3[Customer_ID],Table3[State],"Karnataka") -> Tamil Nadu | K72: =_xlfn.XLOOKUP(Table2[[#This Row],[Customer_ID]],Table3[Customer_ID],Table3[Membership],"Regular") -> Regular | L72: PRD0115 | M72: =_xlfn.XLOOKUP(Table2[[#This Row],[Product_ID]],Table4[Product_ID],Table4[Product_Name],"Not Found") -> Reebok Bodycon Dress Navy Blue | N72: =_xlfn.XLOOKUP(Table2[[#This Row],[Product_ID]],Table4[Product_ID],Table4[Category],"Not Found") -> Women Dresses | O72: =_xlfn.XLOOKUP(Table2[[#This Row],[Product_ID]],Table4[Product_ID],Table4[Subcategory],"Not Found") -> Bodycon Dress | P72: =_xlfn.XLOOKUP(Table2[[#This Row],[Product_ID]],Table4[Product_ID],Table4[Brand],"Missing Brand") -> Reebok | Q72: STR016 | R72: =_xlfn.XLOOKUP(Table2[[#This Row],[Store_ID]],Table6[Store_ID],Table6[Store Name],"Not Found") -> TrendMart Visakhapatnam Flagship | S72: =_xlfn.XLOOKUP(Table2[[#This Row],[Store_ID]],Table6[Store_ID],Table6[Monthly Target],"Missing Target") -> 1200000 | T72: =_xlfn.XLOOKUP(Table2[[#This Row],[Store_ID]],Table6[Store_ID],Table6[Region],"Not Found") -> South Zone 3 | U72: EMP0258 | V72: =_xlfn.XLOOKUP(Table2[[#This Row],[Employee_ID]],Table5[Employee_ID],Table5[Employee Name],"Not Found") -> Preethi Singh | W72: 1 | X72: 1632.35 | Y72: 5 | Z72: 81.62 | AA72: 12 | AB72: 186.09 | AC72: 1736.82 | AD72: 1140.9 | AE72: =(AC72-AD72-AB72) -> 409.83 | AF72: Net Banking | AG72: =IFERROR(Table2[[#This Row],[Profit]]/Table2[[#This Row],[Sales Amount]],0) -> 0.23596573 | AH72: =TRIM(Table2[[#This Row],[Payment Modee]]) -> Net Banking | AI72: Online | AJ72: Not Returned | AK72: 19:45 | AL72: =IF(HOUR(Table2[[#This Row],[Order Time]])<12,"Morning",IF(HOUR(Table2[[#This Row],[Order Time]])<17,"Afternoon",IF(HOUR(Table2[[#This Row],[Order Time]])<21,"Evening","Night"))) -> Evening | AM72: Weekday
A73: INV100072 | B73: 45586 | C73: =YEAR(Table2[[#This Row],[Invoice Date]]) -> 2024 | D73: =TEXT(Table2[[#This Row],[Invoice Date]],"mmm") -> Oct | E73: =Table2[[#This Row],[Store_ID]]&"-"&Table2[[#This Row],[Year]]&"-"&Table2[[#This Row],[Month]] -> STR074-2024-Oct | F73: CUST0338 | G73: =_xlfn.XLOOKUP(Table2[[#This Row],[Customer_ID]],Table3[Customer_ID],Table3[Customer Name],"Not Found") -> Vijay Prasad | H73: =_xlfn.XLOOKUP(Table2[[#This Row],[Customer_ID]],Table3[Customer_ID],Table3[Gender],"Female") -> Male | I73: =_xlfn.XLOOKUP(Table2[[#This Row],[Customer_ID]],Table3[Customer_ID],Table3[City],"Missing Memebership") -> Karimnagar | J73: =_xlfn.XLOOKUP(Table2[[#This Row],[Customer_ID]],Table3[Customer_ID],Table3[State],"Karnataka") -> Telangana | K73: =_xlfn.XLOOKUP(Table2[[#This Row],[Customer_ID]],Table3[Customer_ID],Table3[Membership],"Regular") -> Silver | L73: PRD0034 | M73: =_xlfn.XLOOKUP(Table2[[#This Row],[Product_ID]],Table4[Product_ID],Table4[Product_Name],"Not Found") -> Nike Casual Belt Olive | N73: =_xlfn.XLOOKUP(Table2[[#This Row],[Product_ID]],Table4[Product_ID],Table4[Category],"Not Found") -> Belts | O73: =_xlfn.XLOOKUP(Table2[[#This Row],[Product_ID]],Table4[Product_ID],Table4[Subcategory],"Not Found") -> Casual Belt | P73: =_xlfn.XLOOKUP(Table2[[#This Row],[Product_ID]],Table4[Product_ID],Table4[Brand],"Missing Brand") -> Nike | Q73: STR074 | R73: =_xlfn.XLOOKUP(Table2[[#This Row],[Store_ID]],Table6[Store_ID],Table6[Store Name],"Not Found") -> TrendMart Kurnool High Street | S73: =_xlfn.XLOOKUP(Table2[[#This Row],[Store_ID]],Table6[Store_ID],Table6[Monthly Target],"Missing Target") -> 1200000 | T73: =_xlfn.XLOOKUP(Table2[[#This Row],[Store_ID]],Table6[Store_ID],Table6[Region],"Not Found") -> South Zone 3 | U73: EMP0149 | V73: =_xlfn.XLOOKUP(Table2[[#This Row],[Employee_ID]],Table5[Employee_ID],Table5[Employee Name],"Not Found") -> Vasanthi Kamath | W73: 0 | X73: 413.58 | Y73: 0 | Z73: 0 | AA73: 5 | AB73: 0 | AC73: 0 | AD73: 0 | AE73: 0 | AF73: EMI | AG73: =IFERROR(Table2[[#This Row],[Profit]]/Table2[[#This Row],[Sales Amount]],0) -> 0 | AH73: =TRIM(Table2[[#This Row],[Payment Modee]]) -> EMI | AI73: Online | AJ73: Not Returned | AK73: 21:44 | AL73: =IF(HOUR(Table2[[#This Row],[Order Time]])<12,"Morning",IF(HOUR(Table2[[#This Row],[Order Time]])<17,"Afternoon",IF(HOUR(Table2[[#This Row],[Order Time]])<21,"Evening","Night"))) -> Night | AM73: Weekday
