Workbook
Name Slicer_Region1: #N/A

Sheet Dashboard
A2: TrendMart
A3: Profitability Leakage Analysis
J29: High Sales- Low Profits Products | O29: Top 5 Brands By Profit Margin | S29: KEY INSIGHTS & ACTIONS
J30: Row Labels | K30: Sales | L30: Profit | M30: Margin % | O30: Row Labels | P30: Sales | Q30: Profit | R30: Margin % | S30: 📈 Focus on High Sales – Low Margin Products
J31: Aurelia Earrings Sky Blue | K31: 243671.75 | L31: 31775.83 | M31: 0.09850509 | O31: Arrow | P31: 112698.86 | Q31: 28574.26 | R31: 0.27365496
J32: Global Desi Earrings Green | K32: 207013.85 | L32: 40366.38 | M32: 0.17780678 | O32: Blackberrys | P32: 149336.38 | Q32: 35414.16 | R32: 0.25425815 | S32: 🎯 Increase Online Sales Contribution
J33: Nike Earrings Teal | K33: 173911.74 | L33: 32108.45 | M33: 0.15779037 | O33: Being Human | P33: 115603.02 | Q33: 32170.64 | R33: 0.24888538
J34: Max Fashion Georgette Saree Brown | K34: 138420.26 | L34: 26849.36 | M34: 0.17449247 | O34: Wrangler | P34: 239340.92 | Q34: 61119.52 | R34: 0.23340589 | S34: 🔄 Reduce Return Rate
J35: Global Desi Analog Watch Cream | K35: 133863.46 | L35: 24220.3 | M35: 0.16302135 | O35: Pantaloons | P35: 272553.97 | Q35: 63645.75 | R35: 0.22847732

Sheet Calculations
A2: TOTAL SALES | C2: CURRENT MONTHLY AVG(SALES) | E2: CURRENT MONTHLY AVG(PROFIT) | G2: CURRENT MONTHLY AVG(AVG ORDER VAL)
A3: =SUM(Table2[Sales Amount]) -> 9227180 | C3: =AVERAGE(Sales_Transactions!AC7:AC2997) -> 3073.2408 | E3: =AVERAGE(Sales_Transactions!AE2870:AE2997) -> 558.1843 | G3: =SUM(Sales_Transactions!AC7:AC2997)/COUNTA(Sales_Transactions!AK7:AK2997) -> 3073.2408
A5: TOTAL PROFIT | C5: PREVIOUS MONTHLY AVG(SALES) | E5: PREVIOUS MONTHLY AVG(PROFIT) | G5: PREVIOUS MONTHLY AVG(AVG ORDER VAL)
A6: =SUM(Table2[Profit]) -> 1804518.5 | C6: =AVERAGE(Table2[Sales Amount]) -> 3075.7267 | E6: =AVERAGE(Table2[Profit]) -> 601.50618 | G6: =SUM(Table2[Sales Amount])/COUNTA(Table2[Order Time]) -> 3075.7267
A8: AVERAGE TRANSACTIONS | C8: SALES GROWTH | E8: PROFIT GROWTH | G8: AVG ORDER VALUE GROWTH
A9: =A3/A12 -> 3075.7267 | C9: =((C3-C6)/C6) -> -0.00080821147 | E9: =((E3-E6)/E6) -> -0.072022341 | G9: =((G3-G6)/G6) -> -0.00080821147
A11: TOTAL TRANSACTIONS | C11: =IF(Calculations!C9>=0,"▲ "&TEXT(Calculations!C9,"0.00%")&" vs Last Year","▼ "&TEXT(Calculations!C9,"0.00%")&" vs Last Year") -> ▼ -0.08% vs Last Year | E11: =IF(Calculations!E9>=0,"▲ "&TEXT(Calculations!E9,"0.00%")&" vs Last Year","▼ "&TEXT(Calculations!E9,"0.00%")&" vs Last Year") -> ▼ -7.20% vs Last Year | G11: =IF(Calculations!G9>=0,"▲ "&TEXT(Calculations!G9,"0.00%")&" vs Last Year","▼ "&TEXT(Calculations!G9,"0.00%")&" vs Last Year") -> ▼ -0.08% vs Last Year
A12: =COUNTA(Table2[Invoice No]) -> 3000
A14: PROFIT MARGIN | C14: TOTAL COST
A15: =A6/A3 -> 0.19556555 | C15: =SUM(Table2[Cost Amount]) -> 6596441.1
A17: TOTAL QUANTITY
A18: =SUM(Table2[Quantity]) -> 6118
A20: TOTAL DISCOUNT
A21: =SUM(Table2[Discount Amount]) -> 1184202.8
A23: AVERAGE DISCOUNT
A24: =AVERAGE(Table2[Discount %])/100 -> 0.1257
A26: RETURN RATE
A27: =COUNTIF(Table2[Return Status],"Returned")/COUNTA(Table2[Return Status]) -> 0.048666667

Sheet Pivot Table
A3: Row Labels | B3: Sum of Sales Amount
A4: South Zone 1 | B4: 4463451.9
A5: South Zone 2 | B5: 2554815.9
A6: South Zone 3 | B6: 2208912.1
A7: Grand Total | B7: 9227180
A11: #VALUE!
C18: Row Labels | D18: Sum of Sales Amount
C19: TrendMart Kochi High Street | D19: 386337.29
C20: TrendMart Thiruvananthapuram High Street | D20: 310084.63
C21: TrendMart Kochi Standard | D21: 292305.84
C22: TrendMart Vellore Standard | D22: 264364.77
C23: TrendMart Guntur High Street | D23: 223576.78
C24: TrendMart Nizamabad Standard | D24: 219676.14
C25: TrendMart Thoothukudi Mall Kiosk | D25: 194696.05
C26: TrendMart Chennai Standard | D26: 191070.97
C27: TrendMart Warangal High Street | D27: 190549.81
C28: TrendMart Madurai Mall Kiosk | D28: 188618.31
C29: Grand Total | D29: 2461280.6
A32: Row Labels | B32: Sum of Quantity
A33: GRT Jewellers Sling Bag Olive | B33: 156
A34: Indian Terrain Denim Shirt Wine | B34: 74
A35: Reebok Graphic Tee Cream | B35: 69
A36: Sonata Girls Frock Cream | B36: 68
A37: Jack & Jones Maxi Dress Maroon | B37: 68
A38: Global Desi Round Neck Green | B38: 64
A39: Metro Shoes Polo Purple | B39: 62
A40: Nike Shirt Dress Peach | B40: 61
A41: Peter England Crop Top Green | B41: 57
A42: US Polo Assn Casual Top Sky Blue | B42: 56
A43: Spykar Cotton Saree Black | B43: 56
A44: Grand Total | B44: 791
A48: Row Labels | B48: Sum of Sales Amount
A49: 2024 | B49: 7613439.2
A50: Apr | B50: 683356.93
A51: 45383 | B51: 26253.63
A52: 45384 | B52: 21041.18
A53: 45385 | B53: 25887.06
A54: 45386 | B54: 15719.39
A55: 45387 | B55: 12426.68
A56: 45388 | B56: 41836.48
...

Sheet PT_3
A3: Row Labels | B3: Sum of Sales Amount | C3: Average of Monthly Target | D3: Achievement %
A4: STR001 | B4: 58182.66 | C4: 2500000 | D4: =B4/C4 -> 0.023273064
A5: STR002 | B5: 42708.59 | C5: 1000000 | D5: =B5/C5 -> 0.04270859
A6: STR003 | B6: 60837.5 | C6: 2500000 | D6: =B6/C6 -> 0.024335
A7: STR004 | B7: 125355.94 | C7: 800000 | D7: =B7/C7 -> 0.15669493
A8: STR005 | B8: 47267.33 | C8: 2000000 | D8: =B8/C8 -> 0.023633665
A9: STR006 | B9: 60517.59 | C9: 2000000 | D9: =B9/C9 -> 0.030258795
A10: STR007 | B10: 109813.92 | C10: 1500000 | D10: =B10/C10 -> 0.07320928
A11: STR008 | B11: 88031.94 | C11: 1500000 | D11: =B11/C11 -> 0.05868796
A12: STR009 | B12: 49358.5 | C12: 2500000 | D12: =B12/C12 -> 0.0197434
A13: STR010 | B13: 67231.87 | C13: 2500000 | D13: =B13/C13 -> 0.026892748
A14: STR011 | B14: 129824.86 | C14: 2000000 | D14: =B14/C14 -> 0.06491243
A15: STR012 | B15: 69910.21 | C15: 2000000 | D15: =B15/C15 -> 0.034955105
... A114: STR111 | B114: 71886.83 | C114: 2500000 | D114: =B114/C114 -> 0.028754732
A115: STR112 | B115: 76199.66 | C115: 1500000 | D115: =B115/C115 -> 0.050799773 | G115: Row Labels | H115: Actual Sales | I115: Monthly Target | J115: Achievement %
A116: STR113 | B116: 107652.66 | C116: 2000000 | D116: =B116/C116 -> 0.05382633 | G116: STR037 | H116: 174307.53 | I116: 1000000 | J116: 0.17430753
A117: STR114 | B117: 45249.64 | C117: 2000000 | D117: =B117/C117 -> 0.02262482 | G117: STR004 | H117: 125355.94 | I117: 800000 | J117: 0.15669493
A118: STR115 | B118: 92669.69 | C118: 1500000 | D118: =B118/C118 -> 0.061779793 | G118: STR047 | H118: 99917.88 | I118: 800000 | J118: 0.12489735
A119: STR116 | B119: 72998.49 | C119: 2000000 | D119: =B119/C119 -> 0.036499245 | G119: STR015 | H119: 96001.61 | I119: 800000 | J119: 0.12000201
A120: STR117 | B120: 72445.64 | C120: 1500000 | D120: =B120/C120 -> 0.048297093 | G120: STR052 | H120: 94918.73 | I120: 800000 | J120: 0.11864841
A121: STR118 | B121: 82219.4 | C121: 1000000 | D121: =B121/C121 -> 0.0822194 | G121: STR017 | H121: 8669.72 | I121: 2500000 | J121: 0.003467888
A122: STR119 | B122: 50368.54 | C122: 1000000 | D122: =B122/C122 -> 0.05036854 | G122: STR095 | H122: 21325.26 | I122: 1500000 | J122: 0.01421684
A123: STR120 | B123: 54856.25 | C123: 1500000 | D123: =B123/C123 -> 0.036570833 | G123: STR009 | H123: 49358.5 | I123: 2500000 | J123: 0.0197434
A124: Grand Total | B124: 9227180 | C124: 1615133.3 | G124: STR033 | H124: 54686.2 | I124: 2500000 | J124: 0.02187448
G125: STR114 | H125: 45249.64 | I125: 2000000 | J125: 0.02262482
A126: Row Labels | B126: Sum of Sales Amount | C126: Average of Monthly Target | D126: Achievement %
A127: STR017 | B127: 8669.72 | C127: 2500000 | D127: 0.003467888 | G127: Row Labels | H127: Sum of Actual Sales | I127: Average of Monthly Target | J127: Sum of Achievement %
A128: STR095 | B128: 21325.26 | C128: 1500000 | D128: 0.01421684 | G128: STR037 | H128: 174307.53 | I128: 1000000 | J128: 0.17430753
A129: STR009 | B129: 49358.5 | C129: 2500000 | D129: 0.0197434 | G129: STR004 | H129: 125355.94 | I129: 800000 | J129: 0.15669493
A130: STR033 | B130: 54686.2 | C130: 2500000 | D130: 0.02187448 | G130: STR047 | H130: 99917.88 | I130: 800000 | J130: 0.12489735
A131: STR114 | B131: 45249.64 | C131: 2000000 | D131: 0.02262482 | G131: STR015 | H131: 96001.61 | I131: 800000 | J131: 0.12000201
A132: STR066 | B132: 56611.06 | C132: 2500000 | D132: 0.022644424 | G132: STR052 | H132: 94918.73 | I132: 800000 | J132: 0.11864841
A133: STR061 | B133: 34153.66 | C133: 1500000 | D133: 0.022769107 | G133: STR114 | H133: 45249.64 | I133: 2000000 | J133: 0.02262482
A134: STR001 | B134: 58182.66 | C134: 2500000 | D134: 0.023273064 | G134: STR033 | H134: 54686.2 | I134: 2500000 | J134: 0.02187448
A135: STR005 | B135: 47267.33 | C135: 2000000 | D135: 0.023633665 | G135: STR009 | H135: 49358.5 | I135: 2500000 | J135: 0.0197434
A136: STR079 | B136: 59737.93 | C136: 2500000 | D136: 0.023895172 | G136: STR095 | H136: 21325.26 | I136: 1500000 | J136: 0.01421684
A137: STR026 | B137: 60502.63 | C137: 2500000 | D137: 0.024201052 | G137: STR017 | H137: 8669.72 | I137: 2500000 | J137: 0.003467888
A138: STR003 | B138: 60837.5 | C138: 2500000 | D138: 0.024335
A139: STR081 | B139: 61362.04 | C139: 2500000 | D139: 0.024544816
A140: STR018 | B140: 49189.91 | C140: 2000000 | D140: 0.024594955
...

Sheet PT_2
A3: Row Labels | B3: Sum of Sales Amount | C3: Sum of Profit | G3: Row Labels | H3: Sum of Sales Amount | I3: Sum of Profit
A4: CUST0389 | B4: 0 | C4: 0 | G4: CUST0225 | H4: 59564.98 | I4: 14119.32
A5: CUST0413 | B5: 0 | C5: 0 | G5: CUST0356 | H5: 58389.09 | I5: 8465.81
A6: CUST0019 | B6: 0 | C6: 0 | G6: CUST0821 | H6: 47508.67 | I6: 10001.87
A7: CUST0147 | B7: 0 | C7: 0 | G7: CUST0658 | H7: 43755.92 | I7: 9918.94
A8: CUST0094 | B8: 400.6 | C8: -28.85 | G8: CUST0674 | H8: 42712.27 | I8: 7206.77
A9: CUST0423 | B9: 457.3 | C9: 64.4 | G9: CUST0094 | H9: 400.6 | I9: -28.85
A10: CUST0403 | B10: 461.01 | C10: 144.06 | G10: CUST0423 | H10: 457.3 | I10: 64.4
A11: CUST0455 | B11: 533.44 | C11: -39.09 | G11: CUST0403 | H11: 461.01 | I11: 144.06
A12: CUST0744 | B12: 550.9 | C12: 155.67 | G12: CUST0455 | H12: 533.44 | I12: -39.09
A13: CUST0137 | B13: 554.81 | C13: 184.59 | G13: CUST0744 | H13: 550.9 | I13: 155.67
A14: CUST0134 | B14: 606.77 | C14: -52.38
A15: CUST0020 | B15: 654.7 | C15: 55.46 | F15: Row Labels | G15: Sales Amount | H15: Profit
A16: CUST0662 | B16: 682.2 | C16: 235.21 | F16: CUST0225 | G16: 59564.98 | H16: 14119.32
A17: CUST0416 | B17: 777.32 | C17: 312.14 | F17: CUST0356 | G17: 58389.09 | H17: 8465.81
A18: CUST0317 | B18: 801.17 | C18: 132.76 | F18: CUST0821 | G18: 47508.67 | H18: 10001.87
A19: CUST0048 | B19: 869.65 | C19: 130.16 | F19: CUST0658 | G19: 43755.92 | H19: 9918.94
A20: CUST0436 | B20: 882.02 | C20: 142.52 | F20: CUST0674 | G20: 42712.27 | H20: 7206.77
A21: CUST0357 | B21: 906.44 | C21: 189.1 | F21: CUST0744 | G21: 550.9 | H21: 155.67
A22: CUST0496 | B22: 944.27 | C22: 178.77 | F22: CUST0455 | G22: 533.44 | H22: -39.09
A23: CUST0499 | B23: 979.54 | C23: 71.95 | F23: CUST0403 | G23: 461.01 | H23: 144.06
A24: CUST0828 | B24: 1010.53 | C24: 147.53 | F24: CUST0423 | G24: 457.3 | H24: 64.4
A25: CUST0672 | B25: 1021.57 | C25: 145.01 | F25: CUST0094 | G25: 400.6 | H25: -28.85
A26: CUST0441 | B26: 1025.96 | C26: 172.04 | F26: Grand Total | G26: 254334.18 | H26: 50008.9
A27: CUST0544 | B27: 1034.07 | C27: -23.27
A28: CUST0817 | B28: 1062.99 | C28: 195.37
A29: CUST0399 | B29: 1102.43 | C29: 5.17
A30: CUST0053 | B30: 1133.69 | C30: 332.94
A31: CUST0014 | B31: 1201.14 | C31: 401.7
A32: CUST0378 | B32: 1212.61 | C32: 267.24
A33: CUST0484 | B33: 1212.98 | C33: 221.22
A34: CUST0839 | B34: 1221.63 | C34: 164.84
A35: CUST0719 | B35: 1250.47 | C35: 245.23
A36: CUST0302 | B36: 1263.16 | C36: 285.97
A37: CUST0285 | B37: 1270.07 | C37: 292.14
A38: CUST0548 | B38: 1288.31 | C38: 174.92
... A825: Grand Total | B825: 9227180 | C825: 1804518.5

Sheet PT_1
A3: Row Labels | B3: Sum of Sales Amount | C3: Sum of Profit
A4: 2024 | B4: 7613439.2 | C4: 1489359.7
A5: Apr | B5: 683356.93 | C5: 132559.46
A6: May | B6: 715370.42 | C6: 143214.56
A7: Jun | B7: 706442.99 | C7: 126683.88
A8: Jul | B8: 575940.09 | C8: 110065.95
A9: Aug | B9: 624765.64 | C9: 122773.23
A10: Sep | B10: 842808.66 | C10: 177387.37
A11: Oct | B11: 1519147.1 | C11: 301165.34
A12: Nov | B12: 1054251.4 | C12: 194655.84
A13: Dec | B13: 891356.08 | C13: 180854.07
A14: 2025 | B14: 1613740.7 | C14: 315158.84
A15: Jan | B15: 305174.24 | C15: 54860.77
... A18: Grand Total | B18: 9227180 | C18: 1804518.5
A22: Row Labels | B22: Sum of Sales Amount | C22: Sum of Profit
A23: Women Sarees | B23: 1103017.8 | C23: 202347.57
A24: Handbags | B24: 994021.98 | C24: 213991.74
A25: Watches | B25: 937502.18 | C25: 181304.56
A26: Jewellery | B26: 850930.2 | C26: 150422.21
A27: Women Dresses | B27: 648333.43 | C27: 108303.11
A28: Footwear | B28: 521388.97 | C28: 89384.64
A29: Men Ethnic | B29: 508021.06 | C29: 96328.01
A30: Women Jeans | B30: 504452.21 | C30: 92155.45
A31: Women Kurtis | B31: 408431.14 | C31: 82676.47
A32: Winter Wear | B32: 390745.41 | C32: 82000.54
A33: Grand Total | B33: 6866844.4 | C33: 1298914.3
A49: Row Labels | B49: Sum of Sales Amount | C49: Sum of Cost Amount | D49: Sum of Profit | E49: Sum of Quantity
A50: Sling Bag | B50: 852042.14 | C50: 573553.51 | D50: 188653 | E50: 313
A51: Earrings | B51: 624597.34 | C51: 502154.51 | D51: 104250.66 | E51: 105
A52: Georgette Saree | B52: 470927.8 | C52: 334711 | D52: 85760.28 | E52: 154
A53: Digital Watch | B53: 369648.92 | C53: 268382.4 | D53: 61661.26 | E53: 93
A54: Shirt Dress | B54: 268165.83 | C54: 197365.25 | D54: 42068.57 | E54: 178
A55: Analog Watch | B55: 266092.36 | C55: 190371.93 | D55: 47210.54 | E55: 57
A56: Smart Watch | B56: 249297.22 | C56: 162993.29 | D56: 59593.51 | E56: 78
A57: Printed Saree | B57: 233659.75 | C57: 156760.65 | D57: 51864.11 | E57: 58
A58: Skinny Fit | B58: 223050.53 | C58: 158577.38 | D58: 43341.81 | E58: 185
A59: Slippers | B59: 210364.48 | C59: 144004.46 | D59: 43820.98 | E59: 88
A60: Cotton Saree | B60: 202834.9 | C60: 150333.72 | D60: 30768.88 | E60: 95
A61: Bootcut | B61: 197586.18 | C61: 139405.88 | D61: 37744.2 | E61: 148
... A125: Grand Total | B125: 9227180 | C125: 6596441.1 | D125: 1804518.5 | E125: 6118
...

Sheet Sales_Transactions
A1: Invoice No | B1: Invoice Date | C1: Year | D1: Month | E1: Target Key | F1: Customer_ID | G1: Customer Name | H1: Gender | I1: City | J1: State | K1: Membership | L1: Product_ID | M1: Product_Name | N1: Category | O1: Sub Category | P1: Brand | Q1: Store_ID | R1: Store Name | S1: Monthly Target | T1: Region | U1: Employee_ID | V1: Employee Name | W1: Quantity | X1: Unit Price | Y1: Discount % | Z1: Discount Amount | AA1: GST % | AB1: GST Amount | AC1: Sales Amount | AD1: Cost Amount | AE1: Profit | AF1: Payment Modee | AG1: Profit Margin % | AH1: Payment Mode | AI1: Sales Channel | AJ1: Return Status | AK1: Order Time | AL1: Order Period | AM1: Day Type
A2: INV100001 | B2: 45642 | C2: =YEAR(Table2[[#This Row],[Invoice Date]]) -> 2024 | D2: =TEXT(Table2[[#This Row],[Invoice Date]],"mmm") -> Dec | E2: =Table2[[#This Row],[Store_ID]]&"-"&Table2[[#This Row],[Year]]&"-"&Table2[[#This Row],[Month]] -> STR037-2024-Dec | F2: CUST0052 | G2: =_xlfn.XLOOKUP(Table2[[#This Row],[Customer_ID]],Table3[Customer_ID],Table3[Customer Name],"Not Found") -> Dhruv Achari | H2: =_xlfn.XLOOKUP(Table2[[#This Row],[Customer_ID]],Table3[Customer_ID],Table3[Gender],"Female") -> Male | I2: =_xlfn.XLOOKUP(Table2[[#This Row],[Customer_ID]],Table3[Customer_ID],Table3[City],"Missing Memebership") -> Kollam | J2: =_xlfn.XLOOKUP(Table2[[#This Row],[Customer_ID]],Table3[Customer_ID],Table3[State],"Karnataka") -> Kerala | K2: =_xlfn.XLOOKUP(Table2[[#This Row],[Customer_ID]],Table3[Customer_ID],Table3[Membership],"Regular") -> Regular | L2: PRD0200 | M2: =_xlfn.XLOOKUP(Table2[[#This Row],[Product_ID]],Table4[Product_ID],Table4[Product_Name],"Not Found") -> Pepe Jeans A-Line Kurti White | N2: =_xlfn.XLOOKUP(Table2[[#This Row],[Product_ID]],Table4[Product_ID],Table4[Category],"Not Found") -> Women Kurtis | O2: =_xlfn.XLOOKUP(Table2[[#This Row],[Product_ID]],Table4[Product_ID],Table4[Subcategory],"Not Found") -> A-Line Kurti | P2: =_xlfn.XLOOKUP(Table2[[#This Row],[Product_ID]],Table4[Product_ID],Table4[Brand],"Missing Brand") -> Pepe Jeans | Q2: STR037 | R2: =_xlfn.XLOOKUP(Table2[[#This Row],[Store_ID]],Table6[Store_ID],Table6[Store Name],"Not Found") -> TrendMart Vijayawada High Street | S2: =_xlfn.XLOOKUP(Table2[[#This Row],[Store_ID]],Table6[Store_ID],Table6[Monthly Target],"Missing Target") -> 1000000 | T2: =_xlfn.XLOOKUP(Table2[[#This Row],[Store_ID]],Table6[Store_ID],Table6[Region],"Not Found") -> South Zone 3 | U2: EMP0276 | V2: =_xlfn.XLOOKUP(Table2[[#This Row],[Employee_ID]],Table5[Employee_ID],Table5[Employee Name],"Not Found") -> Manoj Ramachandran | W2: 1 | X2: 749.84 | Y2: 10 | Z2: 74.98 | AA2: 5 | AB2: 33.74 | AC2: 708.6 | AD2: 496.67 | AE2: =(AC2-AD2-AB2) -> 178.19 | AF2: UPI | AG2: =IFERROR(Table2[[#This Row],[Profit]]/Table2[[#This Row],[Sales Amount]],0) -> 0.25146768 | AH2: =TRIM(Table2[[#This Row],[Payment Modee]]) -> UPI | AI2: Offline | AJ2: Not Returned | AK2: 18:16 | AL2: =IF(HOUR(Table2[[#This Row],[Order Time]])<12,"Morning",IF(HOUR(Table2[[#This Row],[Order Time]])<17,"Afternoon",IF(HOUR(Table2[[#This Row],[Order Time]])<21,"Evening","Night"))) -> Evening | AM2: Weekday
A3: INV100002 | B3: 45578 | C3: =YEAR(Table2[[#This Row],[Invoice Date]]) -> 2024 | D3: =TEXT(Table2[[#This Row],[Invoice Date]],"mmm") -> Oct | E3: =Table2[[#This Row],[Store_ID]]&"-"&Table2[[#This Row],[Year]]&"-"&Table2[[#This Row],[Month]] -> STR102-2024-Oct | F3: CUST0463 | G3: =_xlfn.XLOOKUP(Table2[[#This Row],[Customer_ID]],Table3[Customer_ID],Table3[Customer Name],"Not Found") -> Ashok Menon | H3: =_xlfn.XLOOKUP(Table2[[#This Row],[Customer_ID]],Table3[Customer_ID],Table3[Gender],"Female") -> Male | I3: =_xlfn.XLOOKUP(Table2[[#This Row],[Customer_ID]],Table3[Customer_ID],Table3[City],"Missing Memebership") -> Tumakuru | J3: =_xlfn.XLOOKUP(Table2[[#This Row],[Customer_ID]],Table3[Customer_ID],Table3[State],"Karnataka") -> Karnataka | K3: =_xlfn.XLOOKUP(Table2[[#This Row],[Customer_ID]],Table3[Customer_ID],Table3[Membership],"Regular") -> Regular | L3: PRD0245 | M3: =_xlfn.XLOOKUP(Table2[[#This Row],[Product_ID]],Table4[Product_ID],Table4[Product_Name],"Not Found") -> Reebok Round Neck Sky Blue | N3: =_xlfn.XLOOKUP(Table2[[#This Row],[Product_ID]],Table4[Product_ID],Table4[Category],"Not Found") -> Men T-Shirts | O3: =_xlfn.XLOOKUP(Table2[[#This Row],[Product_ID]],Table4[Product_ID],Table4[Subcategory],"Not Found") -> Round Neck | P3: =_xlfn.XLOOKUP(Table2[[#This Row],[Product_ID]],Table4[Product_ID],Table4[Brand],"Missing Brand") -> Reebok | Q3: STR102 | R3: =_xlfn.XLOOKUP(Table2[[#This Row],[Store_ID]],Table6[Store_ID],Table6[Store Name],"Not Found") -> TrendMart Tirunelveli High Street | S3: =_xlfn.XLOOKUP(Table2[[#This Row],[Store_ID]],Table6[Store_ID],Table6[Monthly Target],"Missing Target") -> 1000000 | T3: =_xlfn.XLOOKUP(Table2[[#This Row],[Store_ID]],Table6[Store_ID],Table6[Region],"Not Found") -> South Zone 1 | U3: EMP0156 | V3: =_xlfn.XLOOKUP(Table2[[#This Row],[Employee_ID]],Table5[Employee_ID],Table5[Employee Name],"Not Found") -> Deepthi Iyengar | W3: 2 | X3: 909.55 | Y3: 25 | Z3: 454.77 | AA3: 5 | AB3: 68.22 | AC3: 1432.55 | AD3: 984.22 | AE3: =(AC3-AD3-AB3) -> 380.11 | AF3: Debit Card | AG3: =IFERROR(Table2[[#This Row],[Profit]]/Table2[[#This Row],[Sales Amount]],0) -> 0.26533803 | AH3: =TRIM(Table2[[#This Row],[Payment Modee]]) -> Debit Card | AI3: Online | AJ3: Not Returned | AK3: 13:25 | AL3: =IF(HOUR(Table2[[#This Row],[Order Time]])<12,"Morning",IF(HOUR(Table2[[#This Row],[Order Time]])<17,"Afternoon",IF(HOUR(Table2[[#This Row],[Order Time]])<21,"Evening","Night"))) -> Afternoon | AM3: Weekend
A4: INV100003 | B4: 45657 | C4: =YEAR(Table2[[#This Row],[Invoice Date]]) -> 2024 | D4: =TEXT(Table2[[#This Row],[Invoice Date]],"mmm") -> Dec | E4: =Table2[[#This Row],[Store_ID]]&"-"&Table2[[#This Row],[Year]]&"-"&Table2[[#This Row],[Month]] -> STR011-2024-Dec | F4: CUST0711 | G4: =_xlfn.XLOOKUP(Table2[[#This Row],[Customer_ID]],Table3[Customer_ID],Table3[Customer Name],"Not Found") -> Deepthi Sundaram | H4: =_xlfn.XLOOKUP(Table2[[#This Row],[Customer_ID]],Table3[Customer_ID],Table3[Gender],"Female") -> Female | I4: =_xlfn.XLOOKUP(Table2[[#This Row],[Customer_ID]],Table3[Customer_ID],Table3[City],"Missing Memebership") -> Nellore | J4: =_xlfn.XLOOKUP(Table2[[#This Row],[Customer_ID]],Table3[Customer_ID],Table3[State],"Karnataka") -> Andhra Pradesh | K4: =_xlfn.XLOOKUP(Table2[[#This Row],[Customer_ID]],Table3[Customer_ID],Table3[Membership],"Regular") -> Silver | L4: PRD0065 | M4: =_xlfn.XLOOKUP(Table2[[#This Row],[Product_ID]],Table4[Product_ID],Table4[Product_Name],"Not Found") -> Westside Georgette Saree White | N4: =_xlfn.XLOOKUP(Table2[[#This Row],[Product_ID]],Table4[Product_ID],Table4[Category],"Not Found") -> Women Sarees | O4: =_xlfn.XLOOKUP(Table2[[#This Row],[Product_ID]],Table4[Product_ID],Table4[Subcategory],"Not Found") -> Georgette Saree | P4: =_xlfn.XLOOKUP(Table2[[#This Row],[Product_ID]],Table4[Product_ID],Table4[Brand],"Missing Brand") -> Westside | Q4: STR011 | R4: =_xlfn.XLOOKUP(Table2[[#This Row],[Store_ID]],Table6[Store_ID],Table6[Store Name],"Not Found") -> TrendMart Tirupati Standard | S4: =_xlfn.XLOOKUP(Table2[[#This Row],[Store_ID]],Table6[Store_ID],Table6[Monthly Target],"Missing Target") -> 2000000 | T4: =_xlfn.XLOOKUP(Table2[[#This Row],[Store_ID]],Table6[Store_ID],Table6[Region],"Not Found") -> South Zone 3 | U4: EMP0223 | V4: =_xlfn.XLOOKUP(Table2[[#This Row],[Employee_ID]],Table5[Employee_ID],Table5[Employee Name],"Not Found") -> Meena Krishnan | W4: 2 | X4: 3872.21 | Y4: 0 | Z4: 0 | AA4: 12 | AB4: 929.33 | AC4: 8673.75 | AD4: 5267.12 | AE4: =(AC4-AD4-AB4) -> 2477.3 | AF4: Debit Card | AG4: =IFERROR(Table2[[#This Row],[Profit]]/Table2[[#This Row],[Sales Amount]],0) -> 0.28560888 | AH4: =TRIM(Table2[[#This Row],[Payment Modee]]) -> Debit Card | AI4: Online | AJ4: Not Returned | AK4: 21:10 | AL4: =IF(HOUR(Table2[[#This Row],[Order Time]])<12,"Morning",IF(HOUR(Table2[[#This Row],[Order Time]])<17,"Afternoon",IF(HOUR(Table2[[#This Row],[Order Time]])<21,"Evening","Night"))) -> Night | AM4: Weekday
A5: INV100004 | B5: 45437 | C5: =YEAR(Table2[[#This Row],[Invoice Date]]) -> 2024 | D5: =TEXT(Table2[[#This Row],[Invoice Date]],"mmm") -> May | E5: =Table2[[#This Row],[Store_ID]]&"-"&Table2[[#This Row],[Year]]&"-"&Table2[[#This Row],[Month]] -> STR078-2024-May | F5: CUST0466 | G5: =_xlfn.XLOOKUP(Table2[[#This Row],[Customer_ID]],Table3[Customer_ID],Table3[Customer Name],"Not Found") -> Manoj Varma | H5: =_xlfn.XLOOKUP(Table2[[#This Row],[Customer_ID]],Table3[Customer_ID],Table3[Gender],"Female") -> Male | I5: =_xlfn.XLOOKUP(Table2[[#This Row],[Customer_ID]],Table3[Customer_ID],Table3[City],"Missing Memebership") -> Vellore | J5: =_xlfn.XLOOKUP(Table2[[#This Row],[Customer_ID]],Table3[Customer_ID],Table3[State],"Karnataka") -> Tamil Nadu | K5: =_xlfn.XLOOKUP(Table2[[#This Row],[Customer_ID]],Table3[Customer_ID],Table3[Membership],"Regular") -> Regular | L5: PRD0224 | M5: =_xlfn.XLOOKUP(Table2[[#This Row],[Product_ID]],Table4[Product_ID],Table4[Product_Name],"Not Found") -> Max Fashion Printed Saree Brown | N5: =_xlfn.XLOOKUP(Table2[[#This Row],[Product_ID]],Table4[Product_ID],Table4[Category],"Not Found") -> Women Sarees | O5: =_xlfn.XLOOKUP(Table2[[#This Row],[Product_ID]],Table4[Product_ID],Table4[Subcategory],"Not Found") -> Printed Saree | P5: =_xlfn.XLOOKUP(Table2[[#This Row],[Product_ID]],Table4[Product_ID],Table4[Brand],"Missing Brand") -> Max Fashion | Q5: STR078 | R5: =_xlfn.XLOOKUP(Table2[[#This Row],[Store_ID]],Table6[Store_ID],Table6[Store Name],"Not Found") -> TrendMart Vellore Standard | S5: =_xlfn.XLOOKUP(Table2[[#This Row],[Store_ID]],Table6[Store_ID],Table6[Monthly Target],"Missing Target") -> 1200000 | T5: =_xlfn.XLOOKUP(Table2[[#This Row],[Store_ID]],Table6[Store_ID],Table6[Region],"Not Found") -> South Zone 1 | U5: EMP0170 | V5: =_xlfn.XLOOKUP(Table2[[#This Row],[Employee_ID]],Table5[Employee_ID],Table5[Employee Name],"Not Found") -> Jyothi Prasad | W5: 4 | X5: 4857.75 | Y5: 20 | Z5: 3886.2 | AA5: 12 | AB5: 1865.38 | AC5: 17410.18 | AD5: 13483.2 | AE5: =(AC5-AD5-AB5) -> 2061.6 | AF5: UPI | AG5: =IFERROR(Table2[[#This Row],[Profit]]/Table2[[#This Row],[Sales Amount]],0) -> 0.11841348 | AH5: =TRIM(Table2[[#This Row],[Payment Modee]]) -> UPI | AI5: Online | AJ5: Not Returned | AK5: 13:45 | AL5: =IF(HOUR(Table2[[#This Row],[Order Time]])<12,"Morning",IF(HOUR(Table2[[#This Row],[Order Time]])<17,"Afternoon",IF(HOUR(Table2[[#This Row],[Order Time]])<21,"Evening","Night"))) -> Afternoon | AM5: Weekend
A6: INV100005 | B6: 45487 | C6: =YEAR(Table2[[#This Row],[Invoice Date]]) -> 2024 | D6: =TEXT(Table2[[#This Row],[Invoice Date]],"mmm") -> Jul | E6: =Table2[[#This Row],[Store_ID]]&"-"&Table2[[#This Row],[Year]]&"-"&Table2[[#This Row],[Month]] -> STR058-2024-Jul | F6: CUST0406 | G6: =_xlfn.XLOOKUP(Table2[[#This Row],[Customer_ID]],Table3[Customer_ID],Table3[Customer Name],"Not Found") -> Gayathri Srinivasan | H6: =_xlfn.XLOOKUP(Table2[[#This Row],[Customer_ID]],Table3[Customer_ID],Table3[Gender],"Female") -> Female | I6: =_xlfn.XLOOKUP(Table2[[#This Row],[Customer_ID]],Table3[Customer_ID],Table3[City],"Missing Memebership") -> Vijayawada | J6: =_xlfn.XLOOKUP(Table2[[#This Row],[Customer_ID]],Table3[Customer_ID],Table3[State],"Karnataka") -> Andhra Pradesh | K6: =_xlfn.XLOOKUP(Table2[[#This Row],[Customer_ID]],Table3[Customer_ID],Table3[Membership],"Regular") -> Regular | L6: PRD0035 | M6: =_xlfn.XLOOKUP(Table2[[#This Row],[Product_ID]],Table4[Product_ID],Table4[Product_Name],"Not Found") -> Reebok Printed Kurti Wine | N6: =_xlfn.XLOOKUP(Table2[[#This Row],[Product_ID]],Table4[Product_ID],Table4[Category],"Not Found") -> Women Kurtis | O6: =_xlfn.XLOOKUP(Table2[[#This Row],[Product_ID]],Table4[Product_ID],Table4[Subcategory],"Not Found") -> Printed Kurti | P6: =_xlfn.XLOOKUP(Table2[[#This Row],[Product_ID]],Table4[Product_ID],Table4[Brand],"Missing Brand") -> Reebok | Q6: STR058 | R6: =_xlfn.XLOOKUP(Table2[[#This Row],[Store_ID]],Table6[Store_ID],Table6[Store Name],"Not Found") -> TrendMart Thoothukudi Flagship | S6: =_xlfn.XLOOKUP(Table2[[#This Row],[Store_ID]],Table6[Store_ID],Table6[Monthly Target],"Missing Target") -> 1200000 | T6: =_xlfn.XLOOKUP(Table2[[#This Row],[Store_ID]],Table6[Store_ID],Table6[Region],"Not Found") -> South Zone 1 | U6: EMP0090 | V6: =_xlfn.XLOOKUP(Table2[[#This Row],[Employee_ID]],Table5[Employee_ID],Table5[Employee Name],"Not Found") -> Padma Gounder | W6: 1 | X6: 874.25 | Y6: 0 | Z6: 0 | AA6: 5 | AB6: 43.71 | AC6: 917.96 | AD6: 539.76 | AE6: =(AC6-AD6-AB6) -> 334.49 | AF6: Credit Card | AG6: =IFERROR(Table2[[#This Row],[Profit]]/Table2[[#This Row],[Sales Amount]],0) -> 0.36438407 | AH6: =TRIM(Table2[[#This Row],[Payment Modee]]) -> Credit Card | AI6: Offline | AJ6: Not Returned | AK6: 21:11 | AL6: =IF(HOUR(Table2[[#This Row],[Order Time]])<12,"Morning",IF(HOUR(Table2[[#This Row],[Order Time]])<17,"Afternoon",IF(HOUR(Table2[[#This Row],[Order Time]])<21,"Evening","Night"))) -> Night | AM6: Weekend
A7: INV100006 | B7: 45704 | C7: =YEAR(Table2[[#This Row],[Invoice Date]]) -> 2025 | D7: =TEXT(Table2[[#This Row],[Invoice Date]],"mmm") -> Feb | E7: =Table2[[#This Row],[Store_ID]]&"-"&Table2[[#This Row],[Year]]&"-"&Table2[[#This Row],[Month]] -> STR074-2025-Feb | F7: CUST0084 | G7: =_xlfn.XLOOKUP(Table2[[#This Row],[Customer_ID]],Table3[Customer_ID],Table3[Customer Name],"Not Found") -> Hari Kamath | H7: =_xlfn.XLOOKUP(Table2[[#This Row],[Customer_ID]],Table3[Customer_ID],Table3[Gender],"Female") -> Male | I7: =_xlfn.XLOOKUP(Table2[[#This Row],[Customer_ID]],Table3[Customer_ID],Table3[City],"Missing Memebership") -> Tirupati | J7: =_xlfn.XLOOKUP(Table2[[#This Row],[Customer_ID]],Table3[Customer_ID],Table3[State],"Karnataka") -> Andhra Pradesh | K7: =_xlfn.XLOOKUP(Table2[[#This Row],[Customer_ID]],Table3[Customer_ID],Table3[Membership],"Regular") -> Platinum | L7: PRD0199 | M7: =_xlfn.XLOOKUP(Table2[[#This Row],[Product_ID]],Table4[Product_ID],Table4[Product_Name],"Not Found") -> US Polo Assn Formal Shoes Red | N7: =_xlfn.XLOOKUP(Table2[[#This Row],[Product_ID]],Table4[Product_ID],Table4[Category],"Not Found") -> Footwear | O7: =_xlfn.XLOOKUP(Table2[[#This Row],[Product_ID]],Table4[Product_ID],Table4[Subcategory],"Not Found") -> Formal Shoes | P7: =_xlfn.XLOOKUP(Table2[[#This Row],[Product_ID]],Table4[Product_ID],Table4[Brand],"Missing Brand") -> US Polo Assn | Q7: STR074 | R7: =_xlfn.XLOOKUP(Table2[[#This Row],[Store_ID]],Table6[Store_ID],Table6[Store Name],"Not Found") -> TrendMart Kurnool High Street | S7: =_xlfn.XLOOKUP(Table2[[#This Row],[Store_ID]],Table6[Store_ID],Table6[Monthly Target],"Missing Target") -> 1200000 | T7: =_xlfn.XLOOKUP(Table2[[#This Row],[Store_ID]],Table6[Store_ID],Table6[Region],"Not Found") -> South Zone 3 | U7: EMP0204 | V7: =_xlfn.XLOOKUP(Table2[[#This Row],[Employee_ID]],Table5[Employee_ID],Table5[Employee Name],"Not Found") -> Rahul Krishnan | W7: 2 | X7: 3390.61 | Y7: 30 | Z7: 2034.37 | AA7: 12 | AB7: 569.62 | AC7: 5316.47 | AD7: 4849.24 | AE7: =(AC7-AD7-AB7) -> -102.39 | AF7: Credit Card | AG7: =IFERROR(Table2[[#This Row],[Profit]]/Table2[[#This Row],[Sales Amount]],0) -> -0.01925902 | AH7: =TRIM(Table2[[#This Row],[Payment Modee]]) -> Credit Card | AI7: Offline | AJ7: Not Returned | AK7: 10:24 | AL7: =IF(HOUR(Table2[[#This Row],[Order Time]])<12,"Morning",IF(HOUR(Table2[[#This Row],[Order Time]])<17,"Afternoon",IF(HOUR(Table2[[#This Row],[Order Time]])<21,"Evening","Night"))) -> Morning | AM7: Weekend
A8: INV100007 | B8: 45457 | C8: =YEAR(Table2[[#This Row],[Invoice Date]]) -> 2024 | D8: =TEXT(Table2[[#This Row],[Invoice Date]],"mmm") -> Jun | E8: =Table2[[#This Row],[Store_ID]]&"-"&Table2[[#This Row],[Year]]&"-"&Table2[[#This Row],[Month]] -> STR062-2024-Jun | F8: CUST0714 | G8: =_xlfn.XLOOKUP(Table2[[#This Row],[Customer_ID]],Table3[Customer_ID],Table3[Customer Name],"Not Found") -> Yamini Srinivasan | H8: =_xlfn.XLOOKUP(Table2[[#This Row],[Customer_ID]],Table3[Customer_ID],Table3[Gender],"Female") -> Female | I8: =_xlfn.XLOOKUP(Table2[[#This Row],[Customer_ID]],Table3[Customer_ID],Table3[City],"Missing Memebership") -> Alappuzha | J8: =_xlfn.XLOOKUP(Table2[[#This Row],[Customer_ID]],Table3[Customer_ID],Table3[State],"Karnataka") -> Kerala | K8: =_xlfn.XLOOKUP(Table2[[#This Row],[Customer_ID]],Table3[Customer_ID],Table3[Membership],"Regular") -> Silver | L8: PRD0040 | M8: =_xlfn.XLOOKUP(Table2[[#This Row],[Product_ID]],Table4[Product_ID],Table4[Product_Name],"Not Found") -> US Polo Assn Track Suit Maroon | N8: =_xlfn.XLOOKUP(Table2[[#This Row],[Product_ID]],Table4[Product_ID],Table4[Category],"Not Found") -> Sportswear | O8: =_xlfn.XLOOKUP(Table2[[#This Row],[Product_ID]],Table4[Product_ID],Table4[Subcategory],"Not Found") -> Track Suit | P8: =_xlfn.XLOOKUP(Table2[[#This Row],[Product_ID]],Table4[Product_ID],Table4[Brand],"Missing Brand") -> US Polo Assn | Q8: STR062 | R8: =_xlfn.XLOOKUP(Table2[[#This Row],[Store_ID]],Table6[Store_ID],Table6[Store Name],"Not Found") -> TrendMart Vijayawada Standard | S8: =_xlfn.XLOOKUP(Table2[[#This Row],[Store_ID]],Table6[Store_ID],Table6[Monthly Target],"Missing Target") -> 1000000 | T8: =_xlfn.XLOOKUP(Table2[[#This Row],[Store_ID]],Table6[Store_ID],Table6[Region],"Not Found") -> South Zone 3 | U8: EMP0215 | V8: =_xlfn.XLOOKUP(Table2[[#This Row],[Employee_ID]],Table5[Employee_ID],Table5[Employee Name],"Not Found") -> Praveen Gupta | W8: 4 | X8: 1474.99 | Y8: 0 | Z8: 0 | AA8: 12 | AB8: 708 | AC8: 6607.96 | AD8: 4594.64 | AE8: =(AC8-AD8-AB8) -> 1305.32 | AF8: Cash | AG8: =IFERROR(Table2[[#This Row],[Profit]]/Table2[[#This Row],[Sales Amount]],0) -> 0.19753752 | AH8: =TRIM(Table2[[#This Row],[Payment Modee]]) -> Cash | AI8: Offline | AJ8: Not Returned | AK8: 20:20 | AL8: =IF(HOUR(Table2[[#This Row],[Order Time]])<12,"Morning",IF(HOUR(Table2[[#This Row],[Order Time]])<17,"Afternoon",IF(HOUR(Table2[[#This Row],[Order Time]])<21,"Evening","Night"))) -> Evening | AM8: Weekday
A9: INV100008 | B9: 45678 | C9: =YEAR(Table2[[#This Row],[Invoice Date]]) -> 2025 | D9: =TEXT(Table2[[#This Row],[Invoice Date]],"mmm") -> Jan | E9: =Table2[[#This Row],[Store_ID]]&"-"&Table2[[#This Row],[Year]]&"-"&Table2[[#This Row],[Month]] -> STR084-2025-Jan | F9: CUST0121 | G9: =_xlfn.XLOOKUP(Table2[[#This Row],[Customer_ID]],Table3[Customer_ID],Table3[Customer Name],"Not Found") -> Srinivas Prasad | H9: =_xlfn.XLOOKUP(Table2[[#This Row],[Customer_ID]],Table3[Customer_ID],Table3[Gender],"Female") -> Male | I9: =_xlfn.XLOOKUP(Table2[[#This Row],[Customer_ID]],Table3[Customer_ID],Table3[City],"Missing Memebership") -> Kannur | J9: =_xlfn.XLOOKUP(Table2[[#This Row],[Customer_ID]],Table3[Customer_ID],Table3[State],"Karnataka") -> Kerala | K9: =_xlfn.XLOOKUP(Table2[[#This Row],[Customer_ID]],Table3[Customer_ID],Table3[Membership],"Regular") -> Silver | L9: PRD0196 | M9: =_xlfn.XLOOKUP(Table2[[#This Row],[Product_ID]],Table4[Product_ID],Table4[Product_Name],"Not Found") -> Metro Shoes Slim Fit Wine | N9: =_xlfn.XLOOKUP(Table2[[#This Row],[Product_ID]],Table4[Product_ID],Table4[Category],"Not Found") -> Men Jeans | O9: =_xlfn.XLOOKUP(Table2[[#This Row],[Product_ID]],Table4[Product_ID],Table4[Subcategory],"Not Found") -> Slim Fit | P9: =_xlfn.XLOOKUP(Table2[[#This Row],[Product_ID]],Table4[Product_ID],Table4[Brand],"Missing Brand") -> Metro Shoes | Q9: STR084 | R9: =_xlfn.XLOOKUP(Table2[[#This Row],[Store_ID]],Table6[Store_ID],Table6[Store Name],"Not Found") -> TrendMart Tirupati High Street | S9: =_xlfn.XLOOKUP(Table2[[#This Row],[Store_ID]],Table6[Store_ID],Table6[Monthly Target],"Missing Target") -> 2000000 | T9: =_xlfn.XLOOKUP(Table2[[#This Row],[Store_ID]],Table6[Store_ID],Table6[Region],"Not Found") -> South Zone 3 | U9: EMP0285 | V9: =_xlfn.XLOOKUP(Table2[[#This Row],[Employee_ID]],Table5[Employee_ID],Table5[Employee Name],"Not Found") -> Chandran Krishnan | W9: 1 | X9: 1407.12 | Y9: 0 | Z9: 0 | AA9: 12 | AB9: 168.85 | AC9: 1575.97 | AD9: 1067.72 | AE9: =(AC9-AD9-AB9) -> 339.4 | AF9: UPI | AG9: =IFERROR(Table2[[#This Row],[Profit]]/Table2[[#This Row],[Sales Amount]],0) -> 0.21535943 | AH9: =TRIM(Table2[[#This Row],[Payment Modee]]) -> UPI | AI9: Offline | AJ9: Not Returned | AK9: 21:28 | AL9: =IF(HOUR(Table2[[#This Row],[Order Time]])<12,"Morning",IF(HOUR(Table2[[#This Row],[Order Time]])<17,"Afternoon",IF(HOUR(Table2[[#This Row],[Order Time]])<21,"Evening","Night"))) -> Night | AM9: Weekday
A10: INV100009 | B10: 45541 | C10: =YEAR(Table2[[#This Row],[Invoice Date]]) -> 2024 | D10: =TEXT(Table2[[#This Row],[Invoice Date]],"mmm") -> Sep | E10: =Table2[[#This Row],[Store_ID]]&"-"&Table2[[#This Row],[Year]]&"-"&Table2[[#This Row],[Month]] -> STR021-2024-Sep | F10: CUST0782 | G10: =_xlfn.XLOOKUP(Table2[[#This Row],[Customer_ID]],Table3[Customer_ID],Table3[Customer Name],"Not Found") -> Rahul Yadav | H10: =_xlfn.XLOOKUP(Table2[[#This Row],[Customer_ID]],Table3[Customer_ID],Table3[Gender],"Female") -> Male | I10: =_xlfn.XLOOKUP(Table2[[#This Row],[Customer_ID]],Table3[Customer_ID],Table3[City],"Missing Memebership") -> Alappuzha | J10: =_xlfn.XLOOKUP(Table2[[#This Row],[Customer_ID]],Table3[Customer_ID],Table3[State],"Karnataka") -> Kerala | K10: =_xlfn.XLOOKUP(Table2[[#This Row],[Customer_ID]],Table3[Customer_ID],Table3[Membership],"Regular") -> Gold | L10: PRD0114 | M10: =_xlfn.XLOOKUP(Table2[[#This Row],[Product_ID]],Table4[Product_ID],Table4[Product_Name],"Not Found") -> Arrow Sunglasses Red | N10: =_xlfn.XLOOKUP(Table2[[#This Row],[Product_ID]],Table4[Product_ID],Table4[Category],"Not Found") -> Accessories | O10: =_xlfn.XLOOKUP(Table2[[#This Row],[Product_ID]],Table4[Product_ID],Table4[Subcategory],"Not Found") -> Sunglasses | P10: =_xlfn.XLOOKUP(Table2[[#This Row],[Product_ID]],Table4[Product_ID],Table4[Brand],"Missing Brand") -> Arrow | Q10: STR021 | R10: =_xlfn.XLOOKUP(Table2[[#This Row],[Store_ID]],Table6[Store_ID],Table6[Store Name],"Not Found") -> TrendMart Kozhikode Standard | S10: =_xlfn.XLOOKUP(Table2[[#This Row],[Store_ID]],Table6[Store_ID],Table6[Monthly Target],"Missing Target") -> 2000000 | T10: =_xlfn.XLOOKUP(Table2[[#This Row],[Store_ID]],Table6[Store_ID],Table6[Region],"Not Found") -> South Zone 1 | U10: EMP0001 | V10: =_xlfn.XLOOKUP(Table2[[#This Row],[Employee_ID]],Table5[Employee_ID],Table5[Employee Name],"Not Found") -> Charulatha Kumar | W10: 5 | X10: 851.61 | Y10: 5 | Z10: 212.9 | AA10: 5 | AB10: 202.26 | AC10: 4247.41 | AD10: 2443 | AE10: =(AC10-AD10-AB10) -> 1602.15 | AF10: Debit Card | AG10: =IFERROR(Table2[[#This Row],[Profit]]/Table2[[#This Row],[Sales Amount]],0) -> 0.37720634 | AH10: =TRIM(Table2[[#This Row],[Payment Modee]]) -> Debit Card | AI10: Offline | AJ10: Not Returned | AK10: 19:05 | AL10: =IF(HOUR(Table2[[#This Row],[Order Time]])<12,"Morning",IF(HOUR(Table2[[#This Row],[Order Time]])<17,"Afternoon",IF(HOUR(Table2[[#This Row],[Order Time]])<21,"Evening","Night"))) -> Evening | AM10: Weekday
A11: INV100010 | B11: 45583 | C11: =YEAR(Table2[[#This Row],[Invoice Date]]) -> 2024 | D11: =TEXT(Table2[[#This Row],[Invoice Date]],"mmm") -> Oct | E11: =Table2[[#This Row],[Store_ID]]&"-"&Table2[[#This Row],[Year]]&"-"&Table2[[#This Row],[Month]] -> STR085-2024-Oct | F11: CUST0429 | G11: =_xlfn.XLOOKUP(Table2[[#This Row],[Customer_ID]],Table3[Customer_ID],Table3[Customer Name],"Not Found") -> Nandini Gopalakrishnan | H11: =_xlfn.XLOOKUP(Table2[[#This Row],[Customer_ID]],Table3[Customer_ID],Table3[Gender],"Female") -> Female | I11: =_xlfn.XLOOKUP(Table2[[#This Row],[Customer_ID]],Table3[Customer_ID],Table3[City],"Missing Memebership") -> Vellore | J11: =_xlfn.XLOOKUP(Table2[[#This Row],[Customer_ID]],Table3[Customer_ID],Table3[State],"Karnataka") -> Tamil Nadu | K11: =_xlfn.XLOOKUP(Table2[[#This Row],[Customer_ID]],Table3[Customer_ID],Table3[Membership],"Regular") -> Regular | L11: PRD0075 | M11: =_xlfn.XLOOKUP(Table2[[#This Row],[Product_ID]],Table4[Product_ID],Table4[Product_Name],"Not Found") -> Sonata Bootcut Navy Blue | N11: =_xlfn.XLOOKUP(Table2[[#This Row],[Product_ID]],Table4[Product_ID],Table4[Category],"Not Found") -> Women Jeans | O11: =_xlfn.XLOOKUP(Table2[[#This Row],[Product_ID]],Table4[Product_ID],Table4[Subcategory],"Not Found") -> Bootcut | P11: =_xlfn.XLOOKUP(Table2[[#This Row],[Product_ID]],Table4[Product_ID],Table4[Brand],"Missing Brand") -> Sonata | Q11: STR085 | R11: =_xlfn.XLOOKUP(Table2[[#This Row],[Store_ID]],Table6[Store_ID],Table6[Store Name],"Not Found") -> TrendMart Nizamabad Outlet | S11: =_xlfn.XLOOKUP(Table2[[#This Row],[Store_ID]],Table6[Store_ID],Table6[Monthly Target],"Missing Target") -> 1500000 | T11: =_xlfn.XLOOKUP(Table2[[#This Row],[Store_ID]],Table6[Store_ID],Table6[Region],"Not Found") -> South Zone 2 | U11: EMP0090 | V11: =_xlfn.XLOOKUP(Table2[[#This Row],[Employee_ID]],Table5[Employee_ID],Table5[Employee Name],"Not Found") -> Padma Gounder | W11: 1 | X11: 1041.15 | Y11: 0 | Z11: 0 | AA11: 12 | AB11: 124.94 | AC11: 1166.09 | AD11: 692.53 | AE11: =(AC11-AD11-AB11) -> 348.62 | AF11: Credit Card | AG11: =IFERROR(Table2[[#This Row],[Profit]]/Table2[[#This Row],[Sales Amount]],0) -> 0.29896492 | AH11: =TRIM(Table2[[#This Row],[Payment Modee]]) -> Credit Card | AI11: Offline | AJ11: Not Returned | AK11: 10:34 | AL11: =IF(HOUR(Table2[[#This Row],[Order Time]])<12,"Morning",IF(HOUR(Table2[[#This Row],[Order Time]])<17,"Afternoon",IF(HOUR(Table2[[#This Row],[Order Time]])<21,"Evening","Night"))) -> Morning | AM11: Weekday
A12: INV100011 | B12: 45677 | C12: =YEAR(Table2[[#This Row],[Invoice Date]]) -> 2025 | D12: =TEXT(Table2[[#This Row],[Invoice Date]],"mmm") -> Jan | E12: =Table2[[#This Row],[Store_ID]]&"-"&Table2[[#This Row],[Year]]&"-"&Table2[[#This Row],[Month]] -> STR004-2025-Jan | F12: CUST0162 | G12: =_xlfn.XLOOKUP(Table2[[#This Row],[Customer_ID]],Table3[Customer_ID],Table3[Customer Name],"Not Found") -> Tanvi Balasubramaniam | H12: =_xlfn.XLOOKUP(Table2[[#This Row],[Customer_ID]],Table3[Customer_ID],Table3[Gender],"Female") -> Female | I12: =_xlfn.XLOOKUP(Table2[[#This Row],[Customer_ID]],Table3[Customer_ID],Table3[City],"Missing Memebership") -> Kannur | J12: =_xlfn.XLOOKUP(Table2[[#This Row],[Customer_ID]],Table3[Customer_ID],Table3[State],"Karnataka") -> Kerala | K12: =_xlfn.XLOOKUP(Table2[[#This Row],[Customer_ID]],Table3[Customer_ID],Table3[Membership],"Regular") -> Silver | L12: PRD0117 | M12: =_xlfn.XLOOKUP(Table2[[#This Row],[Product_ID]],Table4[Product_ID],Table4[Product_Name],"Not Found") -> Nike Shirt Dress Peach | N12: =_xlfn.XLOOKUP(Table2[[#This Row],[Product_ID]],Table4[Product_ID],Table4[Category],"Not Found") -> Women Dresses | O12: =_xlfn.XLOOKUP(Table2[[#This Row],[Product_ID]],Table4[Product_ID],Table4[Subcategory],"Not Found") -> Shirt Dress | P12: =_xlfn.XLOOKUP(Table2[[#This Row],[Product_ID]],Table4[Product_ID],Table4[Brand],"Missing Brand") -> Nike | Q12: STR004 | R12: =_xlfn.XLOOKUP(Table2[[#This Row],[Store_ID]],Table6[Store_ID],Table6[Store Name],"Not Found") -> TrendMart Kalaburagi Mall Kiosk | S12: =_xlfn.XLOOKUP(Table2[[#This Row],[Store_ID]],Table6[Store_ID],Table6[Monthly Target],"Missing Target") -> 800000 | T12: =_xlfn.XLOOKUP(Table2[[#This Row],[Store_ID]],Table6[Store_ID],Table6[Region],"Not Found") -> South Zone 2 | U12: EMP0258 | V12: =_xlfn.XLOOKUP(Table2[[#This Row],[Employee_ID]],Table5[Employee_ID],Table5[Employee Name],"Not Found") -> Preethi Singh | W12: 4 | X12: 1761.12 | Y12: 10 | Z12: 704.45 | AA12: 12 | AB12: 760.8 | AC12: 7100.83 | AD12: 5599.4 | AE12: =(AC12-AD12-AB12) -> 740.63 | AF12: Credit Card | AG12: =IFERROR(Table2[[#This Row],[Profit]]/Table2[[#This Row],[Sales Amount]],0) -> 0.10430189 | AH12: =TRIM(Table2[[#This Row],[Payment Modee]]) -> Credit Card | AI12: Offline | AJ12: Not Returned | AK12: 13:20 | AL12: =IF(HOUR(Table2[[#This Row],[Order Time]])<12,"Morning",IF(HOUR(Table2[[#This Row],[Order Time]])<17,"Afternoon",IF(HOUR(Table2[[#This Row],[Order Time]])<21,"Evening","Night"))) -> Afternoon | AM12: Weekday
A13: INV100012 | B13: 45736 | C13: =YEAR(Table2[[#This Row],[Invoice Date]]) -> 2025 | D13: =TEXT(Table2[[#This Row],[Invoice Date]],"mmm") -> Mar | E13: =Table2[[#This Row],[Store_ID]]&"-"&Table2[[#This Row],[Year]]&"-"&Table2[[#This Row],[Month]] -> STR068-2025-Mar | F13: CUST0794 | G13: =_xlfn.XLOOKUP(Table2[[#This Row],[Customer_ID]],Table3[Customer_ID],Table3[Customer Name],"Not Found") -> Rahul Gupta | H13: =_xlfn.XLOOKUP(Table2[[#This Row],[Customer_ID]],Table3[Customer_ID],Table3[Gender],"Female") -> Male | I13: =_xlfn.XLOOKUP(Table2[[#This Row],[Customer_ID]],Table3[Customer_ID],Table3[City],"Missing Memebership") -> Chennai | J13: =_xlfn.XLOOKUP(Table2[[#This Row],[Customer_ID]],Table3[Customer_ID],Table3[State],"Karnataka") -> Tamil Nadu | K13: =_xlfn.XLOOKUP(Table2[[#This Row],[Customer_ID]],Table3[Customer_ID],Table3[Membership],"Regular") -> Silver | L13: PRD0078 | M13: =_xlfn.XLOOKUP(Table2[[#This Row],[Product_ID]],Table4[Product_ID],Table4[Product_Name],"Not Found") -> Metro Shoes Regular Fit Charcoal | N13: =_xlfn.XLOOKUP(Table2[[#This Row],[Product_ID]],Table4[Product_ID],Table4[Category],"Not Found") -> Men Jeans | O13: =_xlfn.XLOOKUP(Table2[[#This Row],[Product_ID]],Table4[Product_ID],Table4[Subcategory],"Not Found") -> Regular Fit | P13: =_xlfn.XLOOKUP(Table2[[#This Row],[Product_ID]],Table4[Product_ID],Table4[Brand],"Missing Brand") -> Metro Shoes | Q13: STR068 | R13: =_xlfn.XLOOKUP(Table2[[#This Row],[Store_ID]],Table6[Store_ID],Table6[Store Name],"Not Found") -> TrendMart Madurai Mall Kiosk | S13: =_xlfn.XLOOKUP(Table2[[#This Row],[Store_ID]],Table6[Store_ID],Table6[Monthly Target],"Missing Target") -> 2000000 | T13: =_xlfn.XLOOKUP(Table2[[#This Row],[Store_ID]],Table6[Store_ID],Table6[Region],"Not Found") -> South Zone 1 | U13: EMP0204 | V13: =_xlfn.XLOOKUP(Table2[[#This Row],[Employee_ID]],Table5[Employee_ID],Table5[Employee Name],"Not Found") -> Rahul Krishnan | W13: 1 | X13: 1019.42 | Y13: 5 | Z13: 50.97 | AA13: 12 | AB13: 116.21 | AC13: 1084.66 | AD13: 828.44 | AE13: =(AC13-AD13-AB13) -> 140.01 | AF13: UPI | AG13: =IFERROR(Table2[[#This Row],[Profit]]/Table2[[#This Row],[Sales Amount]],0) -> 0.12908192 | AH13: =TRIM(Table2[[#This Row],[Payment Modee]]) -> UPI | AI13: Online | AJ13: Not Returned | AK13: 18:28 | AL13: =IF(HOUR(Table2[[#This Row],[Order Time]])<12,"Morning",IF(HOUR(Table2[[#This Row],[Order Time]])<17,"Afternoon",IF(HOUR(Table2[[#This Row],[Order Time]])<21,"Evening","Night"))) -> Evening | AM13: Weekday
... A68: INV100067 | B68: 45622 | C68: =YEAR(Table2[[#This Row],[Invoice Date]]) -> 2024 | D68: =TEXT(Table2[[#This Row],[Invoice Date]],"mmm") -> Nov | E68: =Table2[[#This Row],[Store_ID]]&"-"&Table2[[#This Row],[Year]]&"-"&Table2[[#This Row],[Month]] -> STR100-2024-Nov | F68: CUST0746 | G68: =_xlfn.XLOOKUP(Table2[[#This Row],[Customer_ID]],Table3[Customer_ID],Table3[Customer Name],"Not Found") -> Pandian Venkatesan | H68: =_xlfn.XLOOKUP(Table2[[#This Row],[Customer_ID]],Table3[Customer_ID],Table3[Gender],"Female") -> Male | I68: =_xlfn.XLOOKUP(Table2[[#This Row],[Customer_ID]],Table3[Customer_ID],Table3[City],"Missing Memebership") -> Kalaburagi | J68: =_xlfn.XLOOKUP(Table2[[#This Row],[Customer_ID]],Table3[Customer_ID],Table3[State],"Karnataka") -> Karnataka | K68: =_xlfn.XLOOKUP(Table2[[#This Row],[Customer_ID]],Table3[Customer_ID],Table3[Membership],"Regular") -> Silver | L68: PRD0019 | M68: =_xlfn.XLOOKUP(Table2[[#This Row],[Product_ID]],Table4[Product_ID],Table4[Product_Name],"Not Found") -> Sonata Girls Frock Cream | N68: =_xlfn.XLOOKUP(Table2[[#This Row],[Product_ID]],Table4[Product_ID],Table4[Category],"Not Found") -> Kids Wear | O68: =_xlfn.XLOOKUP(Table2[[#This Row],[Product_ID]],Table4[Product_ID],Table4[Subcategory],"Not Found") -> Kids T-Shirt | P68: =_xlfn.XLOOKUP(Table2[[#This Row],[Product_ID]],Table4[Product_ID],Table4[Brand],"Missing Brand") -> Jack & Jones | Q68: STR100 | R68: =_xlfn.XLOOKUP(Table2[[#This Row],[Store_ID]],Table6[Store_ID],Table6[Store Name],"Not Found") -> TrendMart Hubballi Standard | S68: =_xlfn.XLOOKUP(Table2[[#This Row],[Store_ID]],Table6[Store_ID],Table6[Monthly Target],"Missing Target") -> 2500000 | T68: =_xlfn.XLOOKUP(Table2[[#This Row],[Store_ID]],Table6[Store_ID],Table6[Region],"Not Found") -> South Zone 2 | U68: EMP0141 | V68: =_xlfn.XLOOKUP(Table2[[#This Row],[Employee_ID]],Table5[Employee_ID],Table5[Employee Name],"Not Found") -> Dhruv Mishra | W68: 1 | X68: 640.02 | Y68: 25 | Z68: 160 | AA68: 5 | AB68: 24 | AC68: 504.02 | AD68: 413.39 | AE68: =(AC68-AD68-AB68) -> 66.63 | AF68: Cash | AG68: =IFERROR(Table2[[#This Row],[Profit]]/Table2[[#This Row],[Sales Amount]],0) -> 0.13219714 | AH68: =TRIM(Table2[[#This Row],[Payment Modee]]) -> Cash | AI68: Online | AJ68: Not Returned | AK68: 16:30 | AL68: =IF(HOUR(Table2[[#This Row],[Order Time]])<12,"Morning",IF(HOUR(Table2[[#This Row],[Order Time]])<17,"Afternoon",IF(HOUR(Table2[[#This Row],[Order Time]])<21,"Evening","Night"))) -> Afternoon | AM68: Weekday
A69: INV100068 | B69: 45541 | C69: =YEAR(Table2[[#This Row],[Invoice Date]]) -> 2024 | D69: =TEXT(Table2[[#This Row],[Invoice Date]],"mmm") -> Sep | E69: =Table2[[#This Row],[Store_ID]]&"-"&Table2[[#This Row],[Year]]&"-"&Table2[[#This Row],[Month]] -> STR112-2024-Sep | F69: CUST0583 | G69: =_xlfn.XLOOKUP(Table2[[#This Row],[Customer_ID]],Table3[Customer_ID],Table3[Customer Name],"Not Found") -> Feroz Naicker | H69: =_xlfn.XLOOKUP(Table2[[#This Row],[Customer_ID]],Table3[Customer_ID],Table3[Gender],"Female") -> Male | I69: =_xlfn.XLOOKUP(Table2[[#This Row],[Customer_ID]],Table3[Customer_ID],Table3[City],"Missing Memebership") -> Guntur | J69: =_xlfn.XLOOKUP(Table2[[#This Row],[Customer_ID]],Table3[Customer_ID],Table3[State],"Karnataka") -> Andhra Pradesh | K69: =_xlfn.XLOOKUP(Table2[[#This Row],[Customer_ID]],Table3[Customer_ID],Table3[Membership],"Regular") -> Silver | L69: PRD0134 | M69: =_xlfn.XLOOKUP(Table2[[#This Row],[Product_ID]],Table4[Product_ID],Table4[Product_Name],"Not Found") -> Jack & Jones Maxi Dress Maroon | N69: =_xlfn.XLOOKUP(Table2[[#This Row],[Product_ID]],Table4[Product_ID],Table4[Category],"Not Found") -> Women Dresses | O69: =_xlfn.XLOOKUP(Table2[[#This Row],[Product_ID]],Table4[Product_ID],Table4[Subcategory],"Not Found") -> Maxi Dress | P69: =_xlfn.XLOOKUP(Table2[[#This Row],[Product_ID]],Table4[Product_ID],Table4[Brand],"Missing Brand") -> Jack & Jones | Q69: STR112 | R69: =_xlfn.XLOOKUP(Table2[[#This Row],[Store_ID]],Table6[Store_ID],Table6[Store Name],"Not Found") -> TrendMart Guntur Outlet | S69: =_xlfn.XLOOKUP(Table2[[#This Row],[Store_ID]],Table6[Store_ID],Table6[Monthly Target],"Missing Target") -> 1500000 | T69: =_xlfn.XLOOKUP(Table2[[#This Row],[Store_ID]],Table6[Store_ID],Table6[Region],"Not Found") -> South Zone 3 | U69: EMP0203 | V69: =_xlfn.XLOOKUP(Table2[[#This Row],[Employee_ID]],Table5[Employee_ID],Table5[Employee Name],"Not Found") -> Rani Mishra | W69: 0 | X69: 924.29 | Y69: 0 | Z69: 0 | AA69: 5 | AB69: 0 | AC69: 0 | AD69: 0 | AE69: 0 | AF69: EMI | AG69: =IFERROR(Table2[[#This Row],[Profit]]/Table2[[#This Row],[Sales Amount]],0) -> 0 | AH69: =TRIM(Table2[[#This Row],[Payment Modee]]) -> EMI | AI69: Online | AJ69: Not Returned | AK69: 18:42 | AL69: =IF(HOUR(Table2[[#This Row],[Order Time]])<12,"Morning",IF(HOUR(Table2[[#This Row],[Order Time]])<17,"Afternoon",IF(HOUR(Table2[[#This Row],[Order Time]])<21,"Evening","Night"))) -> Evening | AM69: Weekday
A70: INV100069 | B70: 45622 | C70: =YEAR(Table2[[#This Row],[Invoice Date]]) -> 2024 | D70: =TEXT(Table2[[#This Row],[Invoice Date]],"mmm") -> Nov | E70: =Table2[[#This Row],[Store_ID]]&"-"&Table2[[#This Row],[Year]]&"-"&Table2[[#This Row],[Month]] -> STR088-2024-Nov | F70: CUST0422 | G70: =_xlfn.XLOOKUP(Table2[[#This Row],[Customer_ID]],Table3[Customer_ID],Table3[Customer Name],"Not Found") -> Malathi Shetty | H70: =_xlfn.XLOOKUP(Table2[[#This Row],[Customer_ID]],Table3[Customer_ID],Table3[Gender],"Female") -> Female | I70: =_xlfn.XLOOKUP(Table2[[#This Row],[Customer_ID]],Table3[Customer_ID],Table3[City],"Missing Memebership") -> Nellore | J70: =_xlfn.XLOOKUP(Table2[[#This Row],[Customer_ID]],Table3[Customer_ID],Table3[State],"Karnataka") -> Andhra Pradesh | K70: =_xlfn.XLOOKUP(Table2[[#This Row],[Customer_ID]],Table3[Customer_ID],Table3[Membership],"Regular") -> Silver | L70: PRD0117 | M70: =_xlfn.XLOOKUP(Table2[[#This Row],[Product_ID]],Table4[Product_ID],Table4[Product_Name],"Not Found") -> Nike Shirt Dress Peach | N70: =_xlfn.XLOOKUP(Table2[[#This Row],[Product_ID]],Table4[Product_ID],Table4[Category],"Not Found") -> Women Dresses | O70: =_xlfn.XLOOKUP(Table2[[#This Row],[Product_ID]],Table4[Product_ID],Table4[Subcategory],"Not Found") -> Shirt Dress | P70: =_xlfn.XLOOKUP(Table2[[#This Row],[Product_ID]],Table4[Product_ID],Table4[Brand],"Missing Brand") -> Nike | Q70: STR088 | R70: =_xlfn.XLOOKUP(Table2[[#This Row],[Store_ID]],Table6[Store_ID],Table6[Store Name],"Not Found") -> TrendMart Warangal High Street | S70: =_xlfn.XLOOKUP(Table2[[#This Row],[Store_ID]],Table6[Store_ID],Table6[Monthly Target],"Missing Target") -> 2000000 | T70: =_xlfn.XLOOKUP(Table2[[#This Row],[Store_ID]],Table6[Store_ID],Table6[Region],"Not Found") -> South Zone 2 | U70: EMP0204 | V70: =_xlfn.XLOOKUP(Table2[[#This Row],[Employee_ID]],Table5[Employee_ID],Table5[Employee Name],"Not Found") -> Rahul Krishnan | W70: 2 | X70: 1714.04 | Y70: 10 | Z70: 342.81 | AA70: 12 | AB70: 370.23 | AC70: 3455.5 | AD70: 2799.7 | AE70: =(AC70-AD70-AB70) -> 285.57 | AF70: Cash | AG70: =IFERROR(Table2[[#This Row],[Profit]]/Table2[[#This Row],[Sales Amount]],0) -> 0.082642165 | AH70: =TRIM(Table2[[#This Row],[Payment Modee]]) -> Cash | AI70: Online | AJ70: Not Returned | AK70: 19:44 | AL70: =IF(HOUR(Table2[[#This Row],[Order Time]])<12,"Morning",IF(HOUR(Table2[[#This Row],[Order Time]])<17,"Afternoon",IF(HOUR(Table2[[#This Row],[Order Time]])<21,"Evening","Night"))) -> Evening | AM70: Weekday
A71: INV100070 | B71: 45620 | C71: =YEAR(Table2[[#This Row],[Invoice Date]]) -> 2024 | D71: =TEXT(Table2[[#This Row],[Invoice Date]],"mmm") -> Nov | E71: =Table2[[#This Row],[Store_ID]]&"-"&Table2[[#This Row],[Year]]&"-"&Table2[[#This Row],[Month]] -> STR096-2024-Nov | F71: CUST0613 | G71: =_xlfn.XLOOKUP(Table2[[#This Row],[Customer_ID]],Table3[Customer_ID],Table3[Customer Name],"Not Found") -> Usha Krishnan | H71: =_xlfn.XLOOKUP(Table2[[#This Row],[Customer_ID]],Table3[Customer_ID],Table3[Gender],"Female") -> Female | I71: =_xlfn.XLOOKUP(Table2[[#This Row],[Customer_ID]],Table3[Customer_ID],Table3[City],"Missing Memebership") -> Kalaburagi | J71: =_xlfn.XLOOKUP(Table2[[#This Row],[Customer_ID]],Table3[Customer_ID],Table3[State],"Karnataka") -> Karnataka | K71: =_xlfn.XLOOKUP(Table2[[#This Row],[Customer_ID]],Table3[Customer_ID],Table3[Membership],"Regular") -> Gold | L71: PRD0116 | M71: =_xlfn.XLOOKUP(Table2[[#This Row],[Product_ID]],Table4[Product_ID],Table4[Product_Name],"Not Found") -> Woodland Bootcut Peach | N71: =_xlfn.XLOOKUP(Table2[[#This Row],[Product_ID]],Table4[Product_ID],Table4[Category],"Not Found") -> Women Jeans | O71: =_xlfn.XLOOKUP(Table2[[#This Row],[Product_ID]],Table4[Product_ID],Table4[Subcategory],"Not Found") -> Bootcut | P71: =_xlfn.XLOOKUP(Table2[[#This Row],[Product_ID]],Table4[Product_ID],Table4[Brand],"Missing Brand") -> Woodland | Q71: STR096 | R71: =_xlfn.XLOOKUP(Table2[[#This Row],[Store_ID]],Table6[Store_ID],Table6[Store Name],"Not Found") -> TrendMart Mangaluru Mall Kiosk | S71: =_xlfn.XLOOKUP(Table2[[#This Row],[Store_ID]],Table6[Store_ID],Table6[Monthly Target],"Missing Target") -> 1500000 | T71: =_xlfn.XLOOKUP(Table2[[#This Row],[Store_ID]],Table6[Store_ID],Table6[Region],"Not Found") -> South Zone 2 | U71: EMP0215 | V71: =_xlfn.XLOOKUP(Table2[[#This Row],[Employee_ID]],Table5[Employee_ID],Table5[Employee Name],"Not Found") -> Praveen Gupta | W71: 3 | X71: 1579.45 | Y71: 15 | Z71: 710.75 | AA71: 12 | AB71: 483.31 | AC71: 4510.91 | AD71: 3146.13 | AE71: =(AC71-AD71-AB71) -> 881.47 | AF71: Debit Card | AG71: =IFERROR(Table2[[#This Row],[Profit]]/Table2[[#This Row],[Sales Amount]],0) -> 0.19540847 | AH71: =TRIM(Table2[[#This Row],[Payment Modee]]) -> Debit Card | AI71: Online | AJ71: Not Returned | AK71: 21:51 | AL71: =IF(HOUR(Table2[[#This Row],[Order Time]])<12,"Morning",IF(HOUR(Table2[[#This Row],[Order Time]])<17,"Afternoon",IF(HOUR(Table2[[#This Row],[Order Time]])<21,"Evening","Night"))) -> Night | AM71: Weekend
A72: INV100071 | B72: 45426 | C72: =YEAR(Table2[[#This Row],[Invoice Date]]) -> 2024 | D72: =TEXT(Table2[[#This Row],[Invoice Date]],"mmm") -> May | E72: =Table2[[#This Row],[Store_ID]]&"-"&Table2[[#This Row],[Year]]&"-"&Table2[[#This Row],[Month]] -> STR016-2024-May | F72: CUST0131 | G72: =_xlfn.XLOOKUP(Table2[[#This Row],[Customer_ID]],Table3[Customer_ID],Table3[Customer Name],"Not Found") -> Jyothi Achari | H72: =_xlfn.XLOOKUP(Table2[[#This Row],[Customer_ID]],Table3[Customer_ID],Table3[Gender],"Female") -> Female | I72: =_xlfn.XLOOKUP(Table2[[#This Row],[Customer_ID]],Table3[Customer_ID],Table3[City],"Missing Memebership") -> Tiruchirappalli | J72: =_xlfn.XLOOKUP(Table2[[#This Row],[Customer_ID]],Table3[Customer_ID],Table3[State],"Karnataka") -> Tamil Nadu | K72: =_xlfn.XLOOKUP(Table2[[#This Row],[Customer_ID]],Table3[Customer_ID],Table3[Membership],"Regular") -> Regular | L72: PRD0115 | M72: =_xlfn.XLOOKUP(Table2[[#This Row],[Product_ID]],Table4[Product_ID],Table4[Product_Name],"Not Found") -> Reebok Bodycon Dress Navy Blue | N72: =_xlfn.XLOOKUP(Table2[[#This Row],[Product_ID]],Table4[Product_ID],Table4[Category],"Not Found") -> Women Dresses | O72: =_xlfn.XLOOKUP(Table2[[#This Row],[Product_ID]],Table4[Product_ID],Table4[Subcategory],"Not Found") -> Bodycon Dress | P72: =_xlfn.XLOOKUP(Table2[[#This Row],[Product_ID]],Table4[Product_ID],Table4[Brand],"Missing Brand") -> Reebok | Q72: STR016 | R72: =_xlfn.XLOOKUP(Table2[[#This Row],[Store_ID]],Table6[Store_ID],Table6[Store Name],"Not Found") -> TrendMart Visakhapatnam Flagship | S72: =_xlfn.XLOOKUP(Table2[[#This Row],[Store_ID]],Table6[Store_ID],Table6[Monthly Target],"Missing Target") -> 1200000 | T72: =_xlfn.XLOOKUP(Table2[[#This Row],[Store_ID]],Table6[Store_ID],Table6[Region],"Not Found") -> South Zone 3 | U72: EMP0258 | V72: =_xlfn.XLOOKUP(Table2[[#This Row],[Employee_ID]],Table5[Employee_ID],Table5[Employee Name],"Not Found") -> Preethi Singh | W72: 1 | X72: 1632.35 | Y72: 5 | Z72: 81.62 | AA72: 12 | AB72: 186.09 | AC72: 1736.82 | AD72: 1140.9 | AE72: =(AC72-AD72-AB72) -> 409.83 | AF72: Net Banking | AG72: =IFERROR(Table2[[#This Row],[Profit]]/Table2[[#This Row],[Sales Amount]],0) -> 0.23596573 | AH72: =TRIM(Table2[[#This Row],[Payment Modee]]) -> Net Banking | AI72: Online | AJ72: Not Returned | AK72: 19:45 | AL72: =IF(HOUR(Table2[[#This Row],[Order Time]])<12,"Morning",IF(HOUR(Table2[[#This Row],[Order Time]])<17,"Afternoon",IF(HOUR(Table2[[#This Row],[Order Time]])<21,"Evening","Night"))) -> Evening | AM72: Weekday
A73: INV100072 | B73: 45586 | C73: =YEAR(Table2[[#This Row],[Invoice Date]]) -> 2024 | D73: =TEXT(Table2[[#This Row],[Invoice Date]],"mmm") -> Oct | E73: =Table2[[#This Row],[Store_ID]]&"-"&Table2[[#This Row],[Year]]&"-"&Table2[[#This Row],[Month]] -> STR074-2024-Oct | F73: CUST0338 | G73: =_xlfn.XLOOKUP(Table2[[#This Row],[Customer_ID]],Table3[Customer_ID],Table3[Customer Name],"Not Found") -> Vijay Prasad | H73: =_xlfn.XLOOKUP(Table2[[#This Row],[Customer_ID]],Table3[Customer_ID],Table3[Gender],"Female") -> Male | I73: =_xlfn.XLOOKUP(Table2[[#This Row],[Customer_ID]],Table3[Customer_ID],Table3[City],"Missing Memebership") -> Karimnagar | J73: =_xlfn.XLOOKUP(Table2[[#This Row],[Customer_ID]],Table3[Customer_ID],Table3[State],"Karnataka") -> Telangana | K73: =_xlfn.XLOOKUP(Table2[[#This Row],[Customer_ID]],Table3[Customer_ID],Table3[Membership],"Regular") -> Silver | L73: PRD0034 | M73: =_xlfn.XLOOKUP(Table2[[#This Row],[Product_ID]],Table4[Product_ID],Table4[Product_Name],"Not Found") -> Nike Casual Belt Olive | N73: =_xlfn.XLOOKUP(Table2[[#This Row],[Product_ID]],Table4[Product_ID],Table4[Category],"Not Found") -> Belts | O73: =_xlfn.XLOOKUP(Table2[[#This Row],[Product_ID]],Table4[Product_ID],Table4[Subcategory],"Not Found") -> Casual Belt | P73: =_xlfn.XLOOKUP(Table2[[#This Row],[Product_ID]],Table4[Product_ID],Table4[Brand],"Missing Brand") -> Nike | Q73: STR074 | R73: =_xlfn.XLOOKUP(Table2[[#This Row],[Store_ID]],Table6[Store_ID],Table6[Store Name],"Not Found") -> TrendMart Kurnool High Street | S73: =_xlfn.XLOOKUP(Table2[[#This Row],[Store_ID]],Table6[Store_ID],Table6[Monthly Target],"Missing Target") -> 1200000 | T73: =_xlfn.XLOOKUP(Table2[[#This Row],[Store_ID]],Table6[Store_ID],Table6[Region],"Not Found") -> South Zone 3 | U73: EMP0149 | V73: =_xlfn.XLOOKUP(Table2[[#This Row],[Employee_ID]],Table5[Employee_ID],Table5[Employee Name],"Not Found") -> Vasanthi Kamath | W73: 0 | X73: 413.58 | Y73: 0 | Z73: 0 | AA73: 5 | AB73: 0 | AC73: 0 | AD73: 0 | AE73: 0 | AF73: EMI | AG73: =IFERROR(Table2[[#This Row],[Profit]]/Table2[[#This Row],[Sales Amount]],0) -> 0 | AH73: =TRIM(Table2[[#This Row],[Payment Modee]]) -> EMI | AI73: Online | AJ73: Not Returned | AK73: 21:44 | AL73: =IF(HOUR(Table2[[#This Row],[Order Time]])<12,"Morning",IF(HOUR(Table2[[#This Row],[Order Time]])<17,"Afternoon",IF(HOUR(Table2[[#This Row],[Order Time]])<21,"Evening","Night"))) -> Night | AM73: Weekday
